Workbook

Sheet 00_说明
A1: 项目 | B1: 内容
A2: 文件定位 | B2: 实验计分用轻量工作簿；完整标准答案由非计分展示运行另行导出。
A3: 计算依据 | B3: 同一运行数据库、冻结规则包和核算准入结果。
A4: 公式范围 | B4: 活动水平、产生量、治理后排放量和源级汇总保留Excel公式；完整因子匹配公式见展示运行。

Sheet 02_核算项
A1: 核算项ID | B1: 源ID | C1: 目标源类 | D1: 企业 | E1: 地市 | F1: 行业代码 | G1: 设备类型 | H1: 排放口 | I1: 燃料槽位 | J1: 原始燃料 | K1: 标准燃料 | L1: 标准技术 | M1: 污染物 | N1: 原始消耗量 | O1: 原始单位 | P1: 标准活动水平 | Q1: 活动水平单位 | R1: 活动水平公式 | S1: 参数ID | T1: 因子模式 | U1: 有效因子 | V1: 因子单位 | W1: 因子公式 | X1: 治理技术 | Y1: 治理参数ID | Z1: 去除效率(%) | AA1: PM2.5去除效率(%) | AB1: PM2.5-10去除效率(%) | AC1: 产生量(t) | AD1: 排放量(t) | AE1: 准入状态 | AF1: 准入原因 | AG1: 标志 | AH1: 标准位置 | AI1: 源文件 | AJ1: 源工作表 | AK1: 源行
A2: ITEM-FUEL-SRC-RAW-00533932A04254ABB991-fuel_1-BC | B2: SRC-RAW-00533932A04254ABB991 | C2: POWER | D2: ENT-E97F77765518 | E2: 阳江市 | F2: 4411 | G2: 燃煤锅炉 | H2: DA001 | I2: fuel_1 | J2: 一般烟煤 | K2: 煤炭 | L2: 煤粉炉 | M2: BC | N2: 799951.18 | O2: 吨 | P2: =IF(O2="吨",N2*1000,IF(O2="万立方米",N2*10000,"")) -> 799951180 | Q2: kg | R2: raw_amount*1000 | S2: D-EP-COAL-PF-BC | T2: coal_particle_balance | U2: =0.01269 -> 0.01269 | V2: g/kg燃料 | W2: 10*Aar*(1-ar)*fPM25*fBC | Y2: [] | Z2: 0 | AC2: =P2*U2/1000000 -> 10.15138 | AD2: =AC2*(1-Z2/100) -> 10.15138 | AE2: allow_calculation | AF2: RULE_CHAIN_COMPLETE | AG2: CONTROL_INFO_MISSING_DENOX|CONTROL_INFO_MISSING_DESULF|CONTROL_INFO_MISSING_DUST|CONTROL_MISSING_ZERO|CONTROL_RELATION_CATEGORY_LEVEL | AH2: 附录D 表D.1 p.43 | AI2: /Users/wushuo/Desktop/环境学院论文/固定燃烧源清单经验缺失处置实验/实验结果/02_实验A_端到端清单编制/02_火电热力/01_Full完整方法/R1/inputs/基102-2002_原始结构脱敏输入.xlsx | AJ2: Sheet1 | AK2: 4148
A3: ITEM-FUEL-SRC-RAW-00533932A04254ABB991-fuel_1-CO | B3: SRC-RAW-00533932A04254ABB991 | C3: POWER | D3: ENT-E97F77765518 | E3: 阳江市 | F3: 4411 | G3: 燃煤锅炉 | H3: DA001 | I3: fuel_1 | J3: 一般烟煤 | K3: 煤炭 | L3: 煤粉炉 | M3: CO | N3: 799951.18 | O3: 吨 | P3: =IF(O3="吨",N3*1000,IF(O3="万立方米",N3*10000,"")) -> 799951180 | Q3: kg | R3: raw_amount*1000 | S3: D-EP-COAL-PF-CO | T3: constant | U3: =2.0 -> 2 | V3: g/kg燃料 | W3: constant parameter | Y3: [] | Z3: 0 | AC3: =P3*U3/1000000 -> 1599.9024 | AD3: =AC3*(1-Z3/100) -> 1599.9024 | AE3: allow_calculation | AF3: RULE_CHAIN_COMPLETE | AG3: CONTROL_INFO_MISSING_DENOX|CONTROL_INFO_MISSING_DESULF|CONTROL_INFO_MISSING_DUST|CONTROL_RELATION_CATEGORY_LEVEL|NO_APPLICABLE_CONTROL_ZERO | AH3: 附录D 表D.1 p.43 | AI3: /Users/wushuo/Desktop/环境学院论文/固定燃烧源清单经验缺失处置实验/实验结果/02_实验A_端到端清单编制/02_火电热力/01_Full完整方法/R1/inputs/基102-2002_原始结构脱敏输入.xlsx | AJ3: Sheet1 | AK3: 4148
A4: ITEM-FUEL-SRC-RAW-00533932A04254ABB991-fuel_1-NOX | B4: SRC-RAW-00533932A04254ABB991 | C4: POWER | D4: ENT-E97F77765518 | E4: 阳江市 | F4: 4411 | G4: 燃煤锅炉 | H4: DA001 | I4: fuel_1 | J4: 一般烟煤 | K4: 煤炭 | L4: 煤粉炉 | M4: NOX | N4: 799951.18 | O4: 吨 | P4: =IF(O4="吨",N4*1000,IF(O4="万立方米",N4*10000,"")) -> 799951180 | Q4: kg | R4: raw_amount*1000 | S4: D-EP-COAL-PF-NOX | T4: capacity_lookup | U4: =7.21 -> 7.21 | V4: g/kg燃料 | W4: capacity band | X4: 低氮燃烧技术 | Y4: ["A1-11-NOX"] | Z4: 22 | AC4: =P4*U4/1000000 -> 5767.648 | AD4: =AC4*(1-Z4/100) -> 4498.7654 | AE4: allow_calculation | AF4: RULE_CHAIN_COMPLETE | AG4: CONTROL_INFO_MISSING_DENOX|CONTROL_INFO_MISSING_DESULF|CONTROL_INFO_MISSING_DUST|CONTROL_RELATION_CATEGORY_LEVEL | AH4: 附录D 表D.1 p.43 | AI4: /Users/wushuo/Desktop/环境学院论文/固定燃烧源清单经验缺失处置实验/实验结果/02_实验A_端到端清单编制/02_火电热力/01_Full完整方法/R1/inputs/基102-2002_原始结构脱敏输入.xlsx | AJ4: Sheet1 | AK4: 4148
A5: ITEM-FUEL-SRC-RAW-00533932A04254ABB991-fuel_1-OC | B5: SRC-RAW-00533932A04254ABB991 | C5: POWER | D5: ENT-E97F77765518 | E5: 阳江市 | F5: 4411 | G5: 燃煤锅炉 | H5: DA001 | I5: fuel_1 | J5: 一般烟煤 | K5: 煤炭 | L5: 煤粉炉 | M5: OC | N5: 799951.18 | O5: 吨 | P5: =IF(O5="吨",N5*1000,IF(O5="万立方米",N5*10000,"")) -> 799951180 | Q5: kg | R5: raw_amount*1000 | S5: D-EP-COAL-PF-OC | T5: coal_particle_balance | U5: =0.0 -> 0 | V5: g/kg燃料 | W5: 10*Aar*(1-ar)*fPM25*fOC | Y5: [] | Z5: 0 | AC5: =P5*U5/1000000 -> 0 | AD5: =AC5*(1-Z5/100) -> 0 | AE5: allow_calculation | AF5: RULE_CHAIN_COMPLETE | AG5: CONTROL_INFO_MISSING_DENOX|CONTROL_INFO_MISSING_DESULF|CONTROL_INFO_MISSING_DUST|CONTROL_MISSING_ZERO|CONTROL_RELATION_CATEGORY_LEVEL | AH5: 附录D 表D.1 p.43 | AI5: /Users/wushuo/Desktop/环境学院论文/固定燃烧源清单经验缺失处置实验/实验结果/02_实验A_端到端清单编制/02_火电热力/01_Full完整方法/R1/inputs/基102-2002_原始结构脱敏输入.xlsx | AJ5: Sheet1 | AK5: 4148
A6: ITEM-FUEL-SRC-RAW-00533932A04254ABB991-fuel_1-PM10 | B6: SRC-RAW-00533932A04254ABB991 | C6: POWER | D6: ENT-E97F77765518 | E6: 阳江市 | F6: 4411 | G6: 燃煤锅炉 | H6: DA001 | I6: fuel_1 | J6: 一般烟煤 | K6: 煤炭 | L6: 煤粉炉 | M6: PM10 | N6: 799951.18 | O6: 吨 | P6: =IF(O6="吨",N6*1000,IF(O6="万立方米",N6*10000,"")) -> 799951180 | Q6: kg | R6: raw_amount*1000 | S6: D-EP-COAL-PF-PM10 | T6: coal_particle_balance | U6: =24.3225 -> 24.3225 | V6: g/kg燃料 | W6: 10*Aar*(1-ar)*fPM10 | Y6: [] | Z6: 0 | AA6: 0 | AB6: 0 | AC6: =P6*U6/1000000 -> 19456.813 | AD6: =AC7*(1-AA6/100)+(AC6-AC7)*(1-AB6/100) -> 19456.813 | AE6: allow_calculation | AF6: RULE_CHAIN_COMPLETE | AG6: CONTROL_INFO_MISSING_DENOX|CONTROL_INFO_MISSING_DESULF|CONTROL_INFO_MISSING_DUST|CONTROL_MISSING_ZERO|CONTROL_RELATION_CATEGORY_LEVEL | AH6: 附录D 表D.1 p.43 | AI6: /Users/wushuo/Desktop/环境学院论文/固定燃烧源清单经验缺失处置实验/实验结果/02_实验A_端到端清单编制/02_火电热力/01_Full完整方法/R1/inputs/基102-2002_原始结构脱敏输入.xlsx | AJ6: Sheet1 | AK6: 4148
A7: ITEM-FUEL-SRC-RAW-00533932A04254ABB991-fuel_1-PM25 | B7: SRC-RAW-00533932A04254ABB991 | C7: POWER | D7: ENT-E97F77765518 | E7: 阳江市 | F7: 4411 | G7: 燃煤锅炉 | H7: DA001 | I7: fuel_1 | J7: 一般烟煤 | K7: 煤炭 | L7: 煤粉炉 | M7: PM25 | N7: 799951.18 | O7: 吨 | P7: =IF(O7="吨",N7*1000,IF(O7="万立方米",N7*10000,"")) -> 799951180 | Q7: kg | R7: raw_amount*1000 | S7: D-EP-COAL-PF-PM25 | T7: coal_particle_balance | U7: =6.345 -> 6.345 | V7: g/kg燃料 | W7: 10*Aar*(1-ar)*fPM25 | Y7: [] | Z7: 0 | AC7: =P7*U7/1000000 -> 5075.6902 | AD7: =AC7*(1-Z7/100) -> 5075.6902 | AE7: allow_calculation | AF7: RULE_CHAIN_COMPLETE | AG7: CONTROL_INFO_MISSING_DENOX|CONTROL_INFO_MISSING_DESULF|CONTROL_INFO_MISSING_DUST|CONTROL_MISSING_ZERO|CONTROL_RELATION_CATEGORY_LEVEL | AH7: 附录D 表D.1 p.43 | AI7: /Users/wushuo/Desktop/环境学院论文/固定燃烧源清单经验缺失处置实验/实验结果/02_实验A_端到端清单编制/02_火电热力/01_Full完整方法/R1/inputs/基102-2002_原始结构脱敏输入.xlsx | AJ7: Sheet1 | AK7: 4148
A8: ITEM-FUEL-SRC-RAW-00533932A04254ABB991-fuel_1-SO2 | B8: SRC-RAW-00533932A04254ABB991 | C8: POWER | D8: ENT-E97F77765518 | E8: 阳江市 | F8: 4411 | G8: 燃煤锅炉 | H8: DA001 | I8: fuel_1 | J8: 一般烟煤 | K8: 煤炭 | L8: 煤粉炉 | M8: SO2 | N8: 799951.18 | O8: 吨 | P8: =IF(O8="吨",N8*1000,IF(O8="万立方米",N8*10000,"")) -> 799951180 | Q8: kg | R8: raw_amount*1000 | S8: D-EP-COAL-PF-SO2 | T8: coal_sulfur_balance | U8: =11.9 -> 11.9 | V8: g/kg燃料 | W8: 20*S_percent*(1-sr) | Y8: [] | Z8: 0 | AC8: =P8*U8/1000000 -> 9519.419 | AD8: =AC8*(1-Z8/100) -> 9519.419 | AE8: allow_calculation | AF8: RULE_CHAIN_COMPLETE | AG8: CONTROL_INFO_MISSING_DENOX|CONTROL_INFO_MISSING_DESULF|CONTROL_INFO_MISSING_DUST|CONTROL_MISSING_ZERO|CONTROL_RELATION_CATEGORY_LEVEL | AH8: 附录D 表D.1 p.43 | AI8: /Users/wushuo/Desktop/环境学院论文/固定燃烧源清单经验缺失处置实验/实验结果/02_实验A_端到端清单编制/02_火电热力/01_Full完整方法/R1/inputs/基102-2002_原始结构脱敏输入.xlsx | AJ8: Sheet1 | AK8: 4148
A9: ITEM-FUEL-SRC-RAW-00533932A04254ABB991-fuel_1-VOCS | B9: SRC-RAW-00533932A04254ABB991 | C9: POWER | D9: ENT-E97F77765518 | E9: 阳江市 | F9: 4411 | G9: 燃煤锅炉 | H9: DA001 | I9: fuel_1 | J9: 一般烟煤 | K9: 煤炭 | L9: 煤粉炉 | M9: VOCS | N9: 799951.18 | O9: 吨 | P9: =IF(O9="吨",N9*1000,IF(O9="万立方米",N9*10000,"")) -> 799951180 | Q9: kg | R9: raw_amount*1000 | S9: D-EP-COAL-PF-VOCS | T9: constant | U9: =0.04 -> 0.04 | V9: g/kg燃料 | W9: constant parameter | Y9: [] | Z9: 0 | AC9: =P9*U9/1000000 -> 31.998047 | AD9: =AC9*(1-Z9/100) -> 31.998047 | AE9: allow_calculation | AF9: RULE_CHAIN_COMPLETE | AG9: CONTROL_INFO_MISSING_DENOX|CONTROL_INFO_MISSING_DESULF|CONTROL_INFO_MISSING_DUST|CONTROL_RELATION_CATEGORY_LEVEL|NO_APPLICABLE_CONTROL_ZERO | AH9: 附录D 表D.1 p.43 | AI9: /Users/wushuo/Desktop/环境学院论文/固定燃烧源清单经验缺失处置实验/实验结果/02_实验A_端到端清单编制/02_火电热力/01_Full完整方法/R1/inputs/基102-2002_原始结构脱敏输入.xlsx | AJ9: Sheet1 | AK9: 4148
A10: ITEM-SRC-RAW-00533932A04254ABB991-NH3-SLIP | B10: SRC-RAW-00533932A04254ABB991 | C10: POWER | D10: ENT-E97F77765518 | E10: 阳江市 | F10: 4411 | G10: 燃煤锅炉 | H10: DA001 | M10: NH3 | P10: =IF(O10="吨",N10*1000,IF(O10="万立方米",N10*10000,"")) -> 0 | Q10: kg_coal | R10: SUM(适用煤炭活动水平kg) | T10: empirical_zero | U10: =0.0 -> 0 | V10: g/kg煤 | W10: 脱硝信息缺失按0 | Y10: [] | Z10: 0 | AC10: =P10*U10/1000000 -> 0 | AD10: =AC10*(1-Z10/100) -> 0 | AE10: allow_calculation | AF10: RULE_CHAIN_COMPLETE | AG10: CONTROL_RELATION_CATEGORY_LEVEL|DENITRIFICATION_INFO_MISSING_ZERO | AH10: 经验缺失处置规则 p. | AI10: /Users/wushuo/Desktop/环境学院论文/固定燃烧源清单经验缺失处置实验/实验结果/02_实验A_端到端清单编制/02_火电热力/01_Full完整方法/R1/inputs/基102-2002_原始结构脱敏输入.xlsx | AJ10: Sheet1 | AK10: 4148
A11: ITEM-FUEL-SRC-RAW-008874CA96532DE69412-fuel_1-BC | B11: SRC-RAW-008874CA96532DE69412 | C11: POWER | D11: ENT-B420E4D245A5 | E11: 湛江市 | F11: 4430 | G11: 燃生物质锅炉 | H11: DA001 | I11: fuel_1 | J11: 生物燃料 | L11: 不分技术 | M11: BC | N11: 9100 | O11: 吨标准煤 | W11: factor not matched | Y11: [] | Z11: 0 | AC11: =P11*U11/1000000 -> 0 | AD11: =AC11*(1-Z11/100) -> 0 | AE11: not_applicable | AF11: FUEL_OUTSIDE_FIXED_FOSSIL_SCOPE | AG11: CONTROL_INFO_MISSING_DENOX|CONTROL_INFO_MISSING_DESULF|CONTROL_INFO_MISSING_DUST|CONTROL_MISSING_ZERO|FACTOR_INPUT_MISSING|FUEL_OUTSIDE_FIXED_FOSSIL_SCOPE | AH11: p. | AI11: /Users/wushuo/Desktop/环境学院论文/固定燃烧源清单经验缺失处置实验/实验结果/02_实验A_端到端清单编制/02_火电热力/01_Full完整方法/R1/inputs/基102-2002_原始结构脱敏输入.xlsx | AJ11: Sheet1 | AK11: 3106
A12: ITEM-FUEL-SRC-RAW-008874CA96532DE69412-fuel_1-CO | B12: SRC-RAW-008874CA96532DE69412 | C12: POWER | D12: ENT-B420E4D245A5 | E12: 湛江市 | F12: 4430 | G12: 燃生物质锅炉 | H12: DA001 | I12: fuel_1 | J12: 生物燃料 | L12: 不分技术 | M12: CO | N12: 9100 | O12: 吨标准煤 | W12: factor not matched | Y12: [] | Z12: 0 | AC12: =P12*U12/1000000 -> 0 | AD12: =AC12*(1-Z12/100) -> 0 | AE12: not_applicable | AF12: FUEL_OUTSIDE_FIXED_FOSSIL_SCOPE | AG12: CONTROL_INFO_MISSING_DENOX|CONTROL_INFO_MISSING_DESULF|CONTROL_INFO_MISSING_DUST|FACTOR_INPUT_MISSING|FUEL_OUTSIDE_FIXED_FOSSIL_SCOPE|NO_APPLICABLE_CONTROL_ZERO | AH12: p. | AI12: /Users/wushuo/Desktop/环境学院论文/固定燃烧源清单经验缺失处置实验/实验结果/02_实验A_端到端清单编制/02_火电热力/01_Full完整方法/R1/inputs/基102-2002_原始结构脱敏输入.xlsx | AJ12: Sheet1 | AK12: 3106
A13: ITEM-FUEL-SRC-RAW-008874CA96532DE69412-fuel_1-NOX | B13: SRC-RAW-008874CA96532DE69412 | C13: POWER | D13: ENT-B420E4D245A5 | E13: 湛江市 | F13: 4430 | G13: 燃生物质锅炉 | H13: DA001 | I13: fuel_1 | J13: 生物燃料 | L13: 不分技术 | M13: NOX | N13: 9100 | O13: 吨标准煤 | W13: factor not matched | Y13: [] | Z13: 0 | AC13: =P13*U13/1000000 -> 0 | AD13: =AC13*(1-Z13/100) -> 0 | AE13: not_applicable | AF13: FUEL_OUTSIDE_FIXED_FOSSIL_SCOPE | AG13: CONTROL_INFO_MISSING_DENOX|CONTROL_INFO_MISSING_DESULF|CONTROL_INFO_MISSING_DUST|CONTROL_MISSING_ZERO|FACTOR_INPUT_MISSING|FUEL_OUTSIDE_FIXED_FOSSIL_SCOPE | AH13: p. | AI13: /Users/wushuo/Desktop/环境学院论文/固定燃烧源清单经验缺失处置实验/实验结果/02_实验A_端到端清单编制/02_火电热力/01_Full完整方法/R1/inputs/基102-2002_原始结构脱敏输入.xlsx | AJ13: Sheet1 | AK13: 3106
A14: ITEM-FUEL-SRC-RAW-008874CA96532DE69412-fuel_1-OC | B14: SRC-RAW-008874CA96532DE69412 | C14: POWER | D14: ENT-B420E4D245A5 | E14: 湛江市 | F14: 4430 | G14: 燃生物质锅炉 | H14: DA001 | I14: fuel_1 | J14: 生物燃料 | L14: 不分技术 | M14: OC | N14: 9100 | O14: 吨标准煤 | W14: factor not matched | Y14: [] | Z14: 0 | AC14: =P14*U14/1000000 -> 0 | AD14: =AC14*(1-Z14/100) -> 0 | AE14: not_applicable | AF14: FUEL_OUTSIDE_FIXED_FOSSIL_SCOPE | AG14: CONTROL_INFO_MISSING_DENOX|CONTROL_INFO_MISSING_DESULF|CONTROL_INFO_MISSING_DUST|CONTROL_MISSING_ZERO|FACTOR_INPUT_MISSING|FUEL_OUTSIDE_FIXED_FOSSIL_SCOPE | AH14: p. | AI14: /Users/wushuo/Desktop/环境学院论文/固定燃烧源清单经验缺失处置实验/实验结果/02_实验A_端到端清单编制/02_火电热力/01_Full完整方法/R1/inputs/基102-2002_原始结构脱敏输入.xlsx | AJ14: Sheet1 | AK14: 3106
A15: ITEM-FUEL-SRC-RAW-008874CA96532DE69412-fuel_1-PM10 | B15: SRC-RAW-008874CA96532DE69412 | C15: POWER | D15: ENT-B420E4D245A5 | E15: 湛江市 | F15: 4430 | G15: 燃生物质锅炉 | H15: DA001 | I15: fuel_1 | J15: 生物燃料 | L15: 不分技术 | M15: PM10 | N15: 9100 | O15: 吨标准煤 | W15: factor not matched | Y15: [] | Z15: 0 | AA15: 0 | AB15: 0 | AC15: =P15*U15/1000000 -> 0 | AD15: =AC16*(1-AA15/100)+(AC15-AC16)*(1-AB15/100) -> 0 | AE15: not_applicable | AF15: FUEL_OUTSIDE_FIXED_FOSSIL_SCOPE | AG15: CONTROL_INFO_MISSING_DENOX|CONTROL_INFO_MISSING_DESULF|CONTROL_INFO_MISSING_DUST|CONTROL_MISSING_ZERO|FACTOR_INPUT_MISSING|FUEL_OUTSIDE_FIXED_FOSSIL_SCOPE | AH15: p. | AI15: /Users/wushuo/Desktop/环境学院论文/固定燃烧源清单经验缺失处置实验/实验结果/02_实验A_端到端清单编制/02_火电热力/01_Full完整方法/R1/inputs/基102-2002_原始结构脱敏输入.xlsx | AJ15: Sheet1 | AK15: 3106
A16: ITEM-FUEL-SRC-RAW-008874CA96532DE69412-fuel_1-PM25 | B16: SRC-RAW-008874CA96532DE69412 | C16: POWER | D16: ENT-B420E4D245A5 | E16: 湛江市 | F16: 4430 | G16: 燃生物质锅炉 | H16: DA001 | I16: fuel_1 | J16: 生物燃料 | L16: 不分技术 | M16: PM25 | N16: 9100 | O16: 吨标准煤 | W16: factor not matched | Y16: [] | Z16: 0 | AC16: =P16*U16/1000000 -> 0 | AD16: =AC16*(1-Z16/100) -> 0 | AE16: not_applicable | AF16: FUEL_OUTSIDE_FIXED_FOSSIL_SCOPE | AG16: CONTROL_INFO_MISSING_DENOX|CONTROL_INFO_MISSING_DESULF|CONTROL_INFO_MISSING_DUST|CONTROL_MISSING_ZERO|FACTOR_INPUT_MISSING|FUEL_OUTSIDE_FIXED_FOSSIL_SCOPE | AH16: p. | AI16: /Users/wushuo/Desktop/环境学院论文/固定燃烧源清单经验缺失处置实验/实验结果/02_实验A_端到端清单编制/02_火电热力/01_Full完整方法/R1/inputs/基102-2002_原始结构脱敏输入.xlsx | AJ16: Sheet1 | AK16: 3106
A17: ITEM-FUEL-SRC-RAW-008874CA96532DE69412-fuel_1-SO2 | B17: SRC-RAW-008874CA96532DE69412 | C17: POWER | D17: ENT-B420E4D245A5 | E17: 湛江市 | F17: 4430 | G17: 燃生物质锅炉 | H17: DA001 | I17: fuel_1 | J17: 生物燃料 | L17: 不分技术 | M17: SO2 | N17: 9100 | O17: 吨标准煤 | W17: factor not matched | Y17: [] | Z17: 0 | AC17: =P17*U17/1000000 -> 0 | AD17: =AC17*(1-Z17/100) -> 0 | AE17: not_applicable | AF17: FUEL_OUTSIDE_FIXED_FOSSIL_SCOPE | AG17: CONTROL_INFO_MISSING_DENOX|CONTROL_INFO_MISSING_DESULF|CONTROL_INFO_MISSING_DUST|CONTROL_MISSING_ZERO|FACTOR_INPUT_MISSING|FUEL_OUTSIDE_FIXED_FOSSIL_SCOPE | AH17: p. | AI17: /Users/wushuo/Desktop/环境学院论文/固定燃烧源清单经验缺失处置实验/实验结果/02_实验A_端到端清单编制/02_火电热力/01_Full完整方法/R1/inputs/基102-2002_原始结构脱敏输入.xlsx | AJ17: Sheet1 | AK17: 3106
A18: ITEM-FUEL-SRC-RAW-008874CA96532DE69412-fuel_1-VOCS | B18: SRC-RAW-008874CA96532DE69412 | C18: POWER | D18: ENT-B420E4D245A5 | E18: 湛江市 | F18: 4430 | G18: 燃生物质锅炉 | H18: DA001 | I18: fuel_1 | J18: 生物燃料 | L18: 不分技术 | M18: VOCS | N18: 9100 | O18: 吨标准煤 | W18: factor not matched | Y18: [] | Z18: 0 | AC18: =P18*U18/1000000 -> 0 | AD18: =AC18*(1-Z18/100) -> 0 | AE18: not_applicable | AF18: FUEL_OUTSIDE_FIXED_FOSSIL_SCOPE | AG18: CONTROL_INFO_MISSING_DENOX|CONTROL_INFO_MISSING_DESULF|CONTROL_INFO_MISSING_DUST|FACTOR_INPUT_MISSING|FUEL_OUTSIDE_FIXED_FOSSIL_SCOPE|NO_APPLICABLE_CONTROL_ZERO | AH18: p. | AI18: /Users/wushuo/Desktop/环境学院论文/固定燃烧源清单经验缺失处置实验/实验结果/02_实验A_端到端清单编制/02_火电热力/01_Full完整方法/R1/inputs/基102-2002_原始结构脱敏输入.xlsx | AJ18: Sheet1 | AK18: 3106
A19: ITEM-SRC-RAW-008874CA96532DE69412-NH3-SLIP | B19: SRC-RAW-008874CA96532DE69412 | C19: POWER | D19: ENT-B420E4D245A5 | E19: 湛江市 | F19: 4430 | G19: 燃生物质锅炉 | H19: DA001 | M19: NH3 | P19: =IF(O19="吨",N19*1000,IF(O19="万立方米",N19*10000,"")) -> 0 | Q19: kg_coal | R19: SUM(适用煤炭活动水平kg) | T19: empirical_zero | U19: =0.0 -> 0 | V19: g/kg煤 | W19: 脱硝信息缺失按0 | Y19: [] | Z19: 0 | AC19: =P19*U19/1000000 -> 0 | AD19: =AC19*(1-Z19/100) -> 0 | AE19: allow_calculation | AF19: RULE_CHAIN_COMPLETE | AG19: DENITRIFICATION_INFO_MISSING_ZERO | AH19: 经验缺失处置规则 p. | AI19: /Users/wushuo/Desktop/环境学院论文/固定燃烧源清单经验缺失处置实验/实验结果/02_实验A_端到端清单编制/02_火电热力/01_Full完整方法/R1/inputs/基102-2002_原始结构脱敏输入.xlsx | AJ19: Sheet1 | AK19: 3106
A20: ITEM-FUEL-SRC-RAW-00C256E474D31C7B6CE7-fuel_1-BC | B20: SRC-RAW-00C256E474D31C7B6CE7 | C20: POWER | D20: ENT-092298654969 | E20: 湛江市 | F20: 4411 | G20: 燃煤锅炉 | H20: DA002 | I20: fuel_1 | J20: 一般烟煤 | K20: 煤炭 | L20: 煤粉炉 | M20: BC | N20: 590169 | O20: 吨 | P20: =IF(O20="吨",N20*1000,IF(O20="万立方米",N20*10000,"")) -> 590169000 | Q20: kg | R20: raw_amount*1000 | S20: D-EP-COAL-PF-BC | T20: coal_particle_balance | U20: =0.015740999999999998 -> 0.015741 | V20: g/kg燃料 | W20: 10*Aar*(1-ar)*fPM25*fBC | X20: 电袋复合除尘法 | Y20: ["A1-19-BC", "A1-22-BC", "A1-23-BC", "A1-13-BC"] | Z20: 96 | AC20: =P20*U20/1000000 -> 9.2898502 | AD20: =AC20*(1-Z20/100) -> 0.37159401 | AE20: allow_calculation | AF20: RULE_CHAIN_COMPLETE | AG20: CONTROL_RELATION_AMBIGUOUS|CONTROL_RELATION_CATEGORY_LEVEL|MULTI_PROCESS_MAX_DEFAULT | AH20: 附录D 表D.1 p.43 | AI20: /Users/wushuo/Desktop/环境学院论文/固定燃烧源清单经验缺失处置实验/实验结果/02_实验A_端到端清单编制/02_火电热力/01_Full完整方法/R1/inputs/基102-2002_原始结构脱敏输入.xlsx | AJ20: Sheet1 | AK20: 2926
A21: ITEM-FUEL-SRC-RAW-00C256E474D31C7B6CE7-fuel_1-CO | B21: SRC-RAW-00C256E474D31C7B6CE7 | C21: POWER | D21: ENT-092298654969 | E21: 湛江市 | F21: 4411 | G21: 燃煤锅炉 | H21: DA002 | I21: fuel_1 | J21: 一般烟煤 | K21: 煤炭 | L21: 煤粉炉 | M21: CO | N21: 590169 | O21: 吨 | P21: =IF(O21="吨",N21*1000,IF(O21="万立方米",N21*10000,"")) -> 590169000 | Q21: kg | R21: raw_amount*1000 | S21: D-EP-COAL-PF-CO | T21: constant | U21: =2.0 -> 2 | V21: g/kg燃料 | W21: constant parameter | Y21: [] | Z21: 0 | AC21: =P21*U21/1000000 -> 1180.338 | AD21: =AC21*(1-Z21/100) -> 1180.338 | AE21: allow_calculation | AF21: RULE_CHAIN_COMPLETE | AG21: CONTROL_RELATION_AMBIGUOUS|CONTROL_RELATION_CATEGORY_LEVEL|NO_APPLICABLE_CONTROL_ZERO | AH21: 附录D 表D.1 p.43 | AI21: /Users/wushuo/Desktop/环境学院论文/固定燃烧源清单经验缺失处置实验/实验结果/02_实验A_端到端清单编制/02_火电热力/01_Full完整方法/R1/inputs/基102-2002_原始结构脱敏输入.xlsx | AJ21: Sheet1 | AK21: 2926
A22: ITEM-FUEL-SRC-RAW-00C256E474D31C7B6CE7-fuel_1-NOX | B22: SRC-RAW-00C256E474D31C7B6CE7 | C22: POWER | D22: ENT-092298654969 | E22: 湛江市 | F22: 4411 | G22: 燃煤锅炉 | H22: DA002 | I22: fuel_1 | J22: 一般烟煤 | K22: 煤炭 | L22: 煤粉炉 | M22: NOX | N22: 590169 | O22: 吨 | P22: =IF(O22="吨",N22*1000,IF(O22="万立方米",N22*10000,"")) -> 590169000 | Q22: kg | R22: raw_amount*1000 | S22: D-EP-COAL-PF-NOX | T22: capacity_lookup | U22: =7.21 -> 7.21 | V22: g/kg燃料 | W22: capacity band | X22: 低氮燃烧技术+选择性催化还原法 | Y22: ["A1-15-NOX"] | Z22: 64 | AC22: =P22*U22/1000000 -> 4255.1185 | AD22: =AC22*(1-Z22/100) -> 1531.8427 | AE22: allow_calculation | AF22: RULE_CHAIN_COMPLETE | AG22: CONTROL_RELATION_AMBIGUOUS|CONTROL_RELATION_CATEGORY_LEVEL | AH22: 附录D 表D.1 p.43 | AI22: /Users/wushuo/Desktop/环境学院论文/固定燃烧源清单经验缺失处置实验/实验结果/02_实验A_端到端清单编制/02_火电热力/01_Full完整方法/R1/inputs/基102-2002_原始结构脱敏输入.xlsx | AJ22: Sheet1 | AK22: 2926
A23: ITEM-FUEL-SRC-RAW-00C256E474D31C7B6CE7-fuel_1-OC | B23: SRC-RAW-00C256E474D31C7B6CE7 | C23: POWER | D23: ENT-092298654969 | E23: 湛江市 | F23: 4411 | G23: 燃煤锅炉 | H23: DA002 | I23: fuel_1 | J23: 一般烟煤 | K23: 煤炭 | L23: 煤粉炉 | M23: OC | N23: 590169 | O23: 吨 | P23: =IF(O23="吨",N23*1000,IF(O23="万立方米",N23*10000,"")) -> 590169000 | Q23: kg | R23: raw_amount*1000 | S23: D-EP-COAL-PF-OC | T23: coal_particle_balance | U23: =0.0 -> 0 | V23: g/kg燃料 | W23: 10*Aar*(1-ar)*fPM25*fOC | X23: 电袋复合除尘法 | Y23: ["A1-19-OC", "A1-22-OC", "A1-23-OC", "A1-13-OC"] | Z23: 96 | AC23: =P23*U23/1000000 -> 0 | AD23: =AC23*(1-Z23/100) -> 0 | AE23: allow_calculation | AF23: RULE_CHAIN_COMPLETE | AG23: CONTROL_RELATION_AMBIGUOUS|CONTROL_RELATION_CATEGORY_LEVEL|MULTI_PROCESS_MAX_DEFAULT | AH23: 附录D 表D.1 p.43 | AI23: /Users/wushuo/Desktop/环境学院论文/固定燃烧源清单经验缺失处置实验/实验结果/02_实验A_端到端清单编制/02_火电热力/01_Full完整方法/R1/inputs/基102-2002_原始结构脱敏输入.xlsx | AJ23: Sheet1 | AK23: 2926
A24: ITEM-FUEL-SRC-RAW-00C256E474D31C7B6CE7-fuel_1-PM10 | B24: SRC-RAW-00C256E474D31C7B6CE7 | C24: POWER | D24: ENT-092298654969 | E24: 湛江市 | F24: 4411 | G24: 燃煤锅炉 | H24: DA002 | I24: fuel_1 | J24: 一般烟煤 | K24: 煤炭 | L24: 煤粉炉 | M24: PM10 | N24: 590169 | O24: 吨 | P24: =IF(O24="吨",N24*1000,IF(O24="万立方米",N24*10000,"")) -> 590169000 | Q24: kg | R24: raw_amount*1000 | S24: D-EP-COAL-PF-PM10 | T24: coal_particle_balance | U24: =30.170249999999996 -> 30.17025 | V24: g/kg燃料 | W24: 10*Aar*(1-ar)*fPM10 | X24: 电袋复合除尘法 | Y24: ["A1-13-PM25", "A1-13-PM25_10", "A1-19-PM25", "A1-19-PM25_10", "A1-22-PM25", "A1-22-PM25_10", "A1-23-PM25", "A1-23-PM25_10"] | Z24: 99 | AA24: 96 | AB24: 99 | AC24: =P24*U24/1000000 -> 17805.546 | AD24: =AC25*(1-AA24/100)+(AC24-AC25)*(1-AB24/100) -> 317.40322 | AE24: allow_calculation | AF24: RULE_CHAIN_COMPLETE | AG24: CONTROL_RELATION_AMBIGUOUS|CONTROL_RELATION_CATEGORY_LEVEL|MULTI_PROCESS_MAX_DEFAULT | AH24: 附录D 表D.1 p.43 | AI24: /Users/wushuo/Desktop/环境学院论文/固定燃烧源清单经验缺失处置实验/实验结果/02_实验A_端到端清单编制/02_火电热力/01_Full完整方法/R1/inputs/基102-2002_原始结构脱敏输入.xlsx | AJ24: Sheet1 | AK24: 2926
A25: ITEM-FUEL-SRC-RAW-00C256E474D31C7B6CE7-fuel_1-PM25 | B25: SRC-RAW-00C256E474D31C7B6CE7 | C25: POWER | D25: ENT-092298654969 | E25: 湛江市 | F25: 4411 | G25: 燃煤锅炉 | H25: DA002 | I25: fuel_1 | J25: 一般烟煤 | K25: 煤炭 | L25: 煤粉炉 | M25: PM25 | N25: 590169 | O25: 吨 | P25: =IF(O25="吨",N25*1000,IF(O25="万立方米",N25*10000,"")) -> 590169000 | Q25: kg | R25: raw_amount*1000 | S25: D-EP-COAL-PF-PM25 | T25: coal_particle_balance | U25: =7.870499999999999 -> 7.8705 | V25: g/kg燃料 | W25: 10*Aar*(1-ar)*fPM25 | X25: 电袋复合除尘法 | Y25: ["A1-19-PM25", "A1-22-PM25", "A1-23-PM25", "A1-13-PM25"] | Z25: 96 | AC25: =P25*U25/1000000 -> 4644.9251 | AD25: =AC25*(1-Z25/100) -> 185.797 | AE25: allow_calculation | AF25: RULE_CHAIN_COMPLETE | AG25: CONTROL_RELATION_AMBIGUOUS|CONTROL_RELATION_CATEGORY_LEVEL|MULTI_PROCESS_MAX_DEFAULT | AH25: 附录D 表D.1 p.43 | AI25: /Users/wushuo/Desktop/环境学院论文/固定燃烧源清单经验缺失处置实验/实验结果/02_实验A_端到端清单编制/02_火电热力/01_Full完整方法/R1/inputs/基102-2002_原始结构脱敏输入.xlsx | AJ25: Sheet1 | AK25: 2926
A26: ITEM-FUEL-SRC-RAW-00C256E474D31C7B6CE7-fuel_1-SO2 | B26: SRC-RAW-00C256E474D31C7B6CE7 | C26: POWER | D26: ENT-092298654969 | E26: 湛江市 | F26: 4411 | G26: 燃煤锅炉 | H26: DA002 | I26: fuel_1 | J26: 一般烟煤 | K26: 煤炭 | L26: 煤粉炉 | M26: SO2 | N26: 590169 | O26: 吨 | P26: =IF(O26="吨",N26*1000,IF(O26="万立方米",N26*10000,"")) -> 590169000 | Q26: kg | R26: raw_amount*1000 | S26: D-EP-COAL-PF-SO2 | T26: coal_sulfur_balance | U26: =16.32 -> 16.32 | V26: g/kg燃料 | W26: 20*S_percent*(1-sr) | X26: 其他脱硫技术 | Y26: ["A1-10-SO2", "A1-19-SO2", "A1-10-SO2"] | Z26: 40 | AC26: =P26*U26/1000000 -> 9631.5581 | AD26: =AC26*(1-Z26/100) -> 5778.9348 | AE26: allow_calculation | AF26: RULE_CHAIN_COMPLETE | AG26: CONTROL_RELATION_AMBIGUOUS|CONTROL_RELATION_CATEGORY_LEVEL|MULTI_PROCESS_MAX_DEFAULT | AH26: 附录D 表D.1 p.43 | AI26: /Users/wushuo/Desktop/环境学院论文/固定燃烧源清单经验缺失处置实验/实验结果/02_实验A_端到端清单编制/02_火电热力/01_Full完整方法/R1/inputs/基102-2002_原始结构脱敏输入.xlsx | AJ26: Sheet1 | AK26: 2926
A27: ITEM-FUEL-SRC-RAW-00C256E474D31C7B6CE7-fuel_1-VOCS | B27: SRC-RAW-00C256E474D31C7B6CE7 | C27: POWER | D27: ENT-092298654969 | E27: 湛江市 | F27: 4411 | G27: 燃煤锅炉 | H27: DA002 | I27: fuel_1 | J27: 一般烟煤 | K27: 煤炭 | L27: 煤粉炉 | M27: VOCS | N27: 590169 | O27: 吨 | P27: =IF(O27="吨",N27*1000,IF(O27="万立方米",N27*10000,"")) -> 590169000 | Q27: kg | R27: raw_amount*1000 | S27: D-EP-COAL-PF-VOCS | T27: constant | U27: =0.04 -> 0.04 | V27: g/kg燃料 | W27: constant parameter | Y27: [] | Z27: 0 | AC27: =P27*U27/1000000 -> 23.60676 | AD27: =AC27*(1-Z27/100) -> 23.60676 | AE27: allow_calculation | AF27: RULE_CHAIN_COMPLETE | AG27: CONTROL_RELATION_AMBIGUOUS|CONTROL_RELATION_CATEGORY_LEVEL|NO_APPLICABLE_CONTROL_ZERO | AH27: 附录D 表D.1 p.43 | AI27: /Users/wushuo/Desktop/环境学院论文/固定燃烧源清单经验缺失处置实验/实验结果/02_实验A_端到端清单编制/02_火电热力/01_Full完整方法/R1/inputs/基102-2002_原始结构脱敏输入.xlsx | AJ27: Sheet1 | AK27: 2926
A28: ITEM-SRC-RAW-00C256E474D31C7B6CE7-NH3-SLIP | B28: SRC-RAW-00C256E474D31C7B6CE7 | C28: POWER | D28: ENT-092298654969 | E28: 湛江市 | F28: 4411 | G28: 燃煤锅炉 | H28: DA002 | K28: 煤炭 | L28: 脱硝烟气-选择性催化还原 | M28: NH3 | P28: =IF(O28="吨",N28*1000,IF(O28="万立方米",N28*10000,"")) -> 590169000 | Q28: kg_coal | R28: SUM(适用煤炭活动水平kg) | S28: E1-SCR-NH3 | T28: constant_sum | U28: =0.16 -> 0.16 | V28: g/kg煤 | W28: E1-SCR-NH3 | X28: 脱硝烟气-选择性催化还原 | Y28: ["E1-SCR-NH3"] | Z28: 0 | AC28: =P28*U28/1000000 -> 94.42704 | AD28: =AC28*(1-Z28/100) -> 94.42704 | AE28: allow_calculation | AF28: RULE_CHAIN_COMPLETE | AG28: CONTROL_RELATION_CATEGORY_LEVEL | AH28: 附录E 表E.1 p.50 | AI28: /Users/wushuo/Desktop/环境学院论文/固定燃烧源清单经验缺失处置实验/实验结果/02_实验A_端到端清单编制/02_火电热力/01_Full完整方法/R1/inputs/基102-2002_原始结构脱敏输入.xlsx | AJ28: Sheet1 | AK28: 2926
A29: ITEM-FUEL-SRC-RAW-0109432DE0E295CD5108-fuel_1-BC | B29: SRC-RAW-0109432DE0E295CD5108 | C29: POWER | D29: ENT-8875BA3A892B | E29: 茂名市 | F29: 4411 | G29: 燃煤锅炉 | H29: DA001 | I29: fuel_1 | J29: 一般烟煤 | K29: 煤炭 | L29: 流化床炉 | M29: BC | N29: 105301.9 | O29: 吨 | P29: =IF(O29="吨",N29*1000,IF(O29="万立方米",N29*10000,"")) -> 105301904 | Q29: kg | R29: raw_amount*1000 | S29: D-EP-COAL-CFB-BC | T29: coal_particle_balance | U29: =0.018055520000000005 -> 0.01805552 | V29: g/kg燃料 | W29: 10*Aar*(1-ar)*fPM25*fBC | X29: 普通静电除尘法 | Y29: ["A1-19-BC", "A1-20-BC"] | Z29: 93 | AC29: =P29*U29/1000000 -> 1.9012806 | AD29: =AC29*(1-Z29/100) -> 0.13308964 | AE29: allow_calculation | AF29: RULE_CHAIN_COMPLETE | AG29: CONTROL_INFO_MISSING_DENOX|CONTROL_RELATION_CATEGORY_LEVEL|MULTI_PROCESS_MAX_DEFAULT | AH29: 附录D 表D.1 p.43 | AI29: /Users/wushuo/Desktop/环境学院论文/固定燃烧源清单经验缺失处置实验/实验结果/02_实验A_端到端清单编制/02_火电热力/01_Full完整方法/R1/inputs/基102-2002_原始结构脱敏输入.xlsx | AJ29: Sheet1 | AK29: 3188
A30: ITEM-FUEL-SRC-RAW-0109432DE0E295CD5108-fuel_1-CO | B30: SRC-RAW-0109432DE0E295CD5108 | C30: POWER | D30: ENT-8875BA3A892B | E30: 茂名市 | F30: 4411 | G30: 燃煤锅炉 | H30: DA001 | I30: fuel_1 | J30: 一般烟煤 | K30: 煤炭 | L30: 流化床炉 | M30: CO | N30: 105301.9 | O30: 吨 | P30: =IF(O30="吨",N30*1000,IF(O30="万立方米",N30*10000,"")) -> 105301904 | Q30: kg | R30: raw_amount*1000 | S30: D-EP-COAL-CFB-CO | T30: constant | U30: =2.0 -> 2 | V30: g/kg燃料 | W30: constant parameter | Y30: [] | Z30: 0 | AC30: =P30*U30/1000000 -> 210.60381 | AD30: =AC30*(1-Z30/100) -> 210.60381 | AE30: allow_calculation | AF30: RULE_CHAIN_COMPLETE | AG30: CONTROL_INFO_MISSING_DENOX|CONTROL_RELATION_CATEGORY_LEVEL|NO_APPLICABLE_CONTROL_ZERO | AH30: 附录D 表D.1 p.43 | AI30: /Users/wushuo/Desktop/环境学院论文/固定燃烧源清单经验缺失处置实验/实验结果/02_实验A_端到端清单编制/02_火电热力/01_Full完整方法/R1/inputs/基102-2002_原始结构脱敏输入.xlsx | AJ30: Sheet1 | AK30: 3188
A31: ITEM-FUEL-SRC-RAW-0109432DE0E295CD5108-fuel_1-NOX | B31: SRC-RAW-0109432DE0E295CD5108 | C31: POWER | D31: ENT-8875BA3A892B | E31: 茂名市 | F31: 4411 | G31: 燃煤锅炉 | H31: DA001 | I31: fuel_1 | J31: 一般烟煤 | K31: 煤炭 | L31: 流化床炉 | M31: NOX | N31: 105301.9 | O31: 吨 | P31: =IF(O31="吨",N31*1000,IF(O31="万立方米",N31*10000,"")) -> 105301904 | Q31: kg | R31: raw_amount*1000 | S31: D-EP-COAL-CFB-NOX | T31: capacity_lookup | U31: =8.96 -> 8.96 | V31: g/kg燃料 | W31: capacity band | Y31: [] | Z31: 0 | AC31: =P31*U31/1000000 -> 943.50506 | AD31: =AC31*(1-Z31/100) -> 943.50506 | AE31: allow_calculation | AF31: RULE_CHAIN_COMPLETE | AG31: CONTROL_INFO_MISSING_DENOX|CONTROL_MISSING_ZERO|CONTROL_RELATION_CATEGORY_LEVEL | AH31: 附录D 表D.1 p.43 | AI31: /Users/wushuo/Desktop/环境学院论文/固定燃烧源清单经验缺失处置实验/实验结果/02_实验A_端到端清单编制/02_火电热力/01_Full完整方法/R1/inputs/基102-2002_原始结构脱敏输入.xlsx | AJ31: Sheet1 | AK31: 3188
A32: ITEM-FUEL-SRC-RAW-0109432DE0E295CD5108-fuel_1-OC | B32: SRC-RAW-0109432DE0E295CD5108 | C32: POWER | D32: ENT-8875BA3A892B | E32: 茂名市 | F32: 4411 | G32: 燃煤锅炉 | H32: DA001 | I32: fuel_1 | J32: 一般烟煤 | K32: 煤炭 | L32: 流化床炉 | M32: OC | N32: 105301.9 | O32: 吨 | P32: =IF(O32="吨",N32*1000,IF(O32="万立方米",N32*10000,"")) -> 105301904 | Q32: kg | R32: raw_amount*1000 | S32: D-EP-COAL-CFB-OC | T32: coal_particle_balance | U32: =0.0 -> 0 | V32: g/kg燃料 | W32: 10*Aar*(1-ar)*fPM25*fOC | X32: 普通静电除尘法 | Y32: ["A1-19-OC", "A1-20-OC"] | Z32: 93 | AC32: =P32*U32/1000000 -> 0 | AD32: =AC32*(1-Z32/100) -> 0 | AE32: allow_calculation | AF32: RULE_CHAIN_COMPLETE | AG32: CONTROL_INFO_MISSING_DENOX|CONTROL_RELATION_CATEGORY_LEVEL|MULTI_PROCESS_MAX_DEFAULT | AH32: 附录D 表D.1 p.43 | AI32: /Users/wushuo/Desktop/环境学院论文/固定燃烧源清单经验缺失处置实验/实验结果/02_实验A_端到端清单编制/02_火电热力/01_Full完整方法/R1/inputs/基102-2002_原始结构脱敏输入.xlsx | AJ32: Sheet1 | AK32: 3188
A33: ITEM-FUEL-SRC-RAW-0109432DE0E295CD5108-fuel_1-PM10 | B33: SRC-RAW-0109432DE0E295CD5108 | C33: POWER | D33: ENT-8875BA3A892B | E33: 茂名市 | F33: 4411 | G33: 燃煤锅炉 | H33: DA001 | I33: fuel_1 | J33: 一般烟煤 | K33: 煤炭 | L33: 流化床炉 | M33: PM10 | N33: 105301.9 | O33: 吨 | P33: =IF(O33="吨",N33*1000,IF(O33="万立方米",N33*10000,"")) -> 105301904 | Q33: kg | R33: raw_amount*1000 | S33: D-EP-COAL-CFB-PM10 | T33: coal_particle_balance | U33: =37.40072 -> 37.40072 | V33: g/kg燃料 | W33: 10*Aar*(1-ar)*fPM10 | X33: 普通静电除尘法 | Y33: ["A1-19-PM25", "A1-19-PM25_10", "A1-20-PM25", "A1-20-PM25_10"] | Z33: 98 | AA33: 93 | AB33: 98 | AC33: =P33*U33/1000000 -> 3938.367 | AD33: =AC34*(1-AA33/100)+(AC33-AC34)*(1-AB33/100) -> 126.29936 | AE33: allow_calculation | AF33: RULE_CHAIN_COMPLETE | AG33: CONTROL_INFO_MISSING_DENOX|CONTROL_RELATION_CATEGORY_LEVEL|MULTI_PROCESS_MAX_DEFAULT | AH33: 附录D 表D.1 p.43 | AI33: /Users/wushuo/Desktop/环境学院论文/固定燃烧源清单经验缺失处置实验/实验结果/02_实验A_端到端清单编制/02_火电热力/01_Full完整方法/R1/inputs/基102-2002_原始结构脱敏输入.xlsx | AJ33: Sheet1 | AK33: 3188
A34: ITEM-FUEL-SRC-RAW-0109432DE0E295CD5108-fuel_1-PM25 | B34: SRC-RAW-0109432DE0E295CD5108 | C34: POWER | D34: ENT-8875BA3A892B | E34: 茂名市 | F34: 4411 | G34: 燃煤锅炉 | H34: DA001 | I34: fuel_1 | J34: 一般烟煤 | K34: 煤炭 | L34: 流化床炉 | M34: PM25 | N34: 105301.9 | O34: 吨 | P34: =IF(O34="吨",N34*1000,IF(O34="万立方米",N34*10000,"")) -> 105301904 | Q34: kg | R34: raw_amount*1000 | S34: D-EP-COAL-CFB-PM25 | T34: coal_particle_balance | U34: =9.027760000000002 -> 9.02776 | V34: g/kg燃料 | W34: 10*Aar*(1-ar)*fPM25 | X34: 普通静电除尘法 | Y34: ["A1-19-PM25", "A1-20-PM25"] | Z34: 93 | AC34: =P34*U34/1000000 -> 950.64032 | AD34: =AC34*(1-Z34/100) -> 66.544822 | AE34: allow_calculation | AF34: RULE_CHAIN_COMPLETE | AG34: CONTROL_INFO_MISSING_DENOX|CONTROL_RELATION_CATEGORY_LEVEL|MULTI_PROCESS_MAX_DEFAULT | AH34: 附录D 表D.1 p.43 | AI34: /Users/wushuo/Desktop/环境学院论文/固定燃烧源清单经验缺失处置实验/实验结果/02_实验A_端到端清单编制/02_火电热力/01_Full完整方法/R1/inputs/基102-2002_原始结构脱敏输入.xlsx | AJ34: Sheet1 | AK34: 3188
A35: ITEM-FUEL-SRC-RAW-0109432DE0E295CD5108-fuel_1-SO2 | B35: SRC-RAW-0109432DE0E295CD5108 | C35: POWER | D35: ENT-8875BA3A892B | E35: 茂名市 | F35: 4411 | G35: 燃煤锅炉 | H35: DA001 | I35: fuel_1 | J35: 一般烟煤 | K35: 煤炭 | L35: 流化床炉 | M35: SO2 | N35: 105301.9 | O35: 吨 | P35: =IF(O35="吨",N35*1000,IF(O35="万立方米",N35*10000,"")) -> 105301904 | Q35: kg | R35: raw_amount*1000 | S35: D-EP-COAL-CFB-SO2 | T35: coal_sulfur_balance | U35: =13.09 -> 13.09 | V35: g/kg燃料 | W35: 20*S_percent*(1-sr) | X35: 其他脱硫技术 | Y35: ["A1-10-SO2", "A1-19-SO2", "A1-10-SO2"] | Z35: 40 | AC35: =P35*U35/1000000 -> 1378.4019 | AD35: =AC35*(1-Z35/100) -> 827.04115 | AE35: allow_calculation | AF35: RULE_CHAIN_COMPLETE | AG35: CONTROL_INFO_MISSING_DENOX|CONTROL_RELATION_CATEGORY_LEVEL|MULTI_PROCESS_MAX_DEFAULT | AH35: 附录D 表D.1 p.43 | AI35: /Users/wushuo/Desktop/环境学院论文/固定燃烧源清单经验缺失处置实验/实验结果/02_实验A_端到端清单编制/02_火电热力/01_Full完整方法/R1/inputs/基102-2002_原始结构脱敏输入.xlsx | AJ35: Sheet1 | AK35: 3188
A36: ITEM-FUEL-SRC-RAW-0109432DE0E295CD5108-fuel_1-VOCS | B36: SRC-RAW-0109432DE0E295CD5108 | C36: POWER | D36: ENT-8875BA3A892B | E36: 茂名市 | F36: 4411 | G36: 燃煤锅炉 | H36: DA001 | I36: fuel_1 | J36: 一般烟煤 | K36: 煤炭 | L36: 流化床炉 | M36: VOCS | N36: 105301.9 | O36: 吨 | P36: =IF(O36="吨",N36*1000,IF(O36="万立方米",N36*10000,"")) -> 105301904 | Q36: kg | R36: raw_amount*1000 | S36: D-EP-COAL-CFB-VOCS | T36: constant | U36: =0.04 -> 0.04 | V36: g/kg燃料 | W36: constant parameter | Y36: [] | Z36: 0 | AC36: =P36*U36/1000000 -> 4.2120762 | AD36: =AC36*(1-Z36/100) -> 4.2120762 | AE36: allow_calculation | AF36: RULE_CHAIN_COMPLETE | AG36: CONTROL_INFO_MISSING_DENOX|CONTROL_RELATION_CATEGORY_LEVEL|NO_APPLICABLE_CONTROL_ZERO | AH36: 附录D 表D.1 p.43 | AI36: /Users/wushuo/Desktop/环境学院论文/固定燃烧源清单经验缺失处置实验/实验结果/02_实验A_端到端清单编制/02_火电热力/01_Full完整方法/R1/inputs/基102-2002_原始结构脱敏输入.xlsx | AJ36: Sheet1 | AK36: 3188
A37: ITEM-FUEL-SRC-RAW-0109432DE0E295CD5108-fuel_2-BC | B37: SRC-RAW-0109432DE0E295CD5108 | C37: POWER | D37: ENT-8875BA3A892B | E37: 茂名市 | F37: 4411 | G37: 燃煤锅炉 | H37: DA001 | I37: fuel_2 | J37: 石油焦 | K37: 石油焦 | L37: 燃油锅炉 | M37: BC | N37: 84772.738 | O37: 吨 | P37: =IF(O37="吨",N37*1000,IF(O37="万立方米",N37*10000,"")) -> 84772738 | Q37: kg | R37: raw_amount*1000 | S37: D-EP-PETCOKE-OILBOILER-BC | T37: constant | U37: =0.04 -> 0.04 | V37: g/kg燃料 | W37: constant parameter | X37: 普通静电除尘法 | Y37: ["A1-19-BC", "A1-20-BC"] | Z37: 93 | AC37: =P37*U37/1000000 -> 3.3909095 | AD37: =AC37*(1-Z37/100) -> 0.23736367 | AE37: allow_calculation | AF37: RULE_CHAIN_COMPLETE | AG37: CONTROL_INFO_MISSING_DENOX|CONTROL_RELATION_CATEGORY_LEVEL|MULTI_PROCESS_MAX_DEFAULT | AH37: 附录D 表D.1 p.43 | AI37: /Users/wushuo/Desktop/环境学院论文/固定燃烧源清单经验缺失处置实验/实验结果/02_实验A_端到端清单编制/02_火电热力/01_Full完整方法/R1/inputs/基102-2002_原始结构脱敏输入.xlsx | AJ37: Sheet1 | AK37: 3188
A38: ITEM-FUEL-SRC-RAW-0109432DE0E295CD5108-fuel_2-CO | B38: SRC-RAW-0109432DE0E295CD5108 | C38: POWER | D38: ENT-8875BA3A892B | E38: 茂名市 | F38: 4411 | G38: 燃煤锅炉 | H38: DA001 | I38: fuel_2 | J38: 石油焦 | K38: 石油焦 | L38: 燃油锅炉 | M38: CO | N38: 84772.738 | O38: 吨 | P38: =IF(O38="吨",N38*1000,IF(O38="万立方米",N38*10000,"")) -> 84772738 | Q38: kg | R38: raw_amount*1000 | S38: D-EP-PETCOKE-OILBOILER-CO | T38: constant | U38: =0.6 -> 0.6 | V38: g/kg燃料 | W38: constant parameter | Y38: [] | Z38: 0 | AC38: =P38*U38/1000000 -> 50.863643 | AD38: =AC38*(1-Z38/100) -> 50.863643 | AE38: allow_calculation | AF38: RULE_CHAIN_COMPLETE | AG38: CONTROL_INFO_MISSING_DENOX|CONTROL_RELATION_CATEGORY_LEVEL|NO_APPLICABLE_CONTROL_ZERO | AH38: 附录D 表D.1 p.43 | AI38: /Users/wushuo/Desktop/环境学院论文/固定燃烧源清单经验缺失处置实验/实验结果/02_实验A_端到端清单编制/02_火电热力/01_Full完整方法/R1/inputs/基102-2002_原始结构脱敏输入.xlsx | AJ38: Sheet1 | AK38: 3188
A39: ITEM-FUEL-SRC-RAW-0109432DE0E295CD5108-fuel_2-NOX | B39: SRC-RAW-0109432DE0E295CD5108 | C39: POWER | D39: ENT-8875BA3A892B | E39: 茂名市 | F39: 4411 | G39: 燃煤锅炉 | H39: DA001 | I39: fuel_2 | J39: 石油焦 | K39: 石油焦 | L39: 燃油锅炉 | M39: NOX | N39: 84772.738 | O39: 吨 | P39: =IF(O39="吨",N39*1000,IF(O39="万立方米",N39*10000,"")) -> 84772738 | Q39: kg | R39: raw_amount*1000 | S39: D-EP-PETCOKE-OILBOILER-NOX | T39: constant | U39: =10.06 -> 10.06 | V39: g/kg燃料 | W39: constant parameter | Y39: [] | Z39: 0 | AC39: =P39*U39/1000000 -> 852.81374 | AD39: =AC39*(1-Z39/100) -> 852.81374 | AE39: allow_calculation | AF39: RULE_CHAIN_COMPLETE | AG39: CONTROL_INFO_MISSING_DENOX|CONTROL_MISSING_ZERO|CONTROL_RELATION_CATEGORY_LEVEL | AH39: 附录D 表D.1 p.43 | AI39: /Users/wushuo/Desktop/环境学院论文/固定燃烧源清单经验缺失处置实验/实验结果/02_实验A_端到端清单编制/02_火电热力/01_Full完整方法/R1/inputs/基102-2002_原始结构脱敏输入.xlsx | AJ39: Sheet1 | AK39: 3188
A40: ITEM-FUEL-SRC-RAW-0109432DE0E295CD5108-fuel_2-OC | B40: SRC-RAW-0109432DE0E295CD5108 | C40: POWER | D40: ENT-8875BA3A892B | E40: 茂名市 | F40: 4411 | G40: 燃煤锅炉 | H40: DA001 | I40: fuel_2 | J40: 石油焦 | K40: 石油焦 | L40: 燃油锅炉 | M40: OC | N40: 84772.738 | O40: 吨 | P40: =IF(O40="吨",N40*1000,IF(O40="万立方米",N40*10000,"")) -> 84772738 | Q40: kg | R40: raw_amount*1000 | S40: D-EP-PETCOKE-OILBOILER-OC | T40: constant | U40: =0.01 -> 0.01 | V40: g/kg燃料 | W40: constant parameter | X40: 普通静电除尘法 | Y40: ["A1-19-OC", "A1-20-OC"] | Z40: 93 | AC40: =P40*U40/1000000 -> 0.84772738 | AD40: =AC40*(1-Z40/100) -> 0.059340917 | AE40: allow_calculation | AF40: RULE_CHAIN_COMPLETE | AG40: CONTROL_INFO_MISSING_DENOX|CONTROL_RELATION_CATEGORY_LEVEL|MULTI_PROCESS_MAX_DEFAULT | AH40: 附录D 表D.1 p.43 | AI40: /Users/wushuo/Desktop/环境学院论文/固定燃烧源清单经验缺失处置实验/实验结果/02_实验A_端到端清单编制/02_火电热力/01_Full完整方法/R1/inputs/基102-2002_原始结构脱敏输入.xlsx | AJ40: Sheet1 | AK40: 3188
...

Sheet 03_源结果
A1: 源ID | B1: 企业 | C1: 地市 | D1: 行业代码 | E1: 设备类型 | F1: 排放口 | G1: SO2_产生量(t) | H1: NOX_产生量(t) | I1: CO_产生量(t) | J1: VOCS_产生量(t) | K1: PM10_产生量(t) | L1: PM25_产生量(t) | M1: BC_产生量(t) | N1: OC_产生量(t) | O1: NH3_产生量(t) | P1: SO2_排放量(t) | Q1: NOX_排放量(t) | R1: CO_排放量(t) | S1: VOCS_排放量(t) | T1: PM10_排放量(t) | U1: PM25_排放量(t) | V1: BC_排放量(t) | W1: OC_排放量(t) | X1: NH3_排放量(t) | Y1: 异常标志数
A2: SRC-RAW-00533932A04254ABB991 | B2: ENT-E97F77765518 | C2: 阳江市 | D2: 4411 | E2: 燃煤锅炉 | F2: DA001 | G2: =SUMIFS('02_核算项'!$AC$2:$AC$6232,'02_核算项'!$B$2:$B$6232,$A2,'02_核算项'!$M$2:$M$6232,"SO2") -> 9519.419 | H2: =SUMIFS('02_核算项'!$AC$2:$AC$6232,'02_核算项'!$B$2:$B$6232,$A2,'02_核算项'!$M$2:$M$6232,"NOX") -> 5767.648 | I2: =SUMIFS('02_核算项'!$AC$2:$AC$6232,'02_核算项'!$B$2:$B$6232,$A2,'02_核算项'!$M$2:$M$6232,"CO") -> 1599.9024 | J2: =SUMIFS('02_核算项'!$AC$2:$AC$6232,'02_核算项'!$B$2:$B$6232,$A2,'02_核算项'!$M$2:$M$6232,"VOCS") -> 31.998047 | K2: =SUMIFS('02_核算项'!$AC$2:$AC$6232,'02_核算项'!$B$2:$B$6232,$A2,'02_核算项'!$M$2:$M$6232,"PM10") -> 19456.813 | L2: =SUMIFS('02_核算项'!$AC$2:$AC$6232,'02_核算项'!$B$2:$B$6232,$A2,'02_核算项'!$M$2:$M$6232,"PM25") -> 5075.6902 | M2: =SUMIFS('02_核算项'!$AC$2:$AC$6232,'02_核算项'!$B$2:$B$6232,$A2,'02_核算项'!$M$2:$M$6232,"BC") -> 10.15138 | N2: =SUMIFS('02_核算项'!$AC$2:$AC$6232,'02_核算项'!$B$2:$B$6232,$A2,'02_核算项'!$M$2:$M$6232,"OC") -> 0 | O2: =SUMIFS('02_核算项'!$AC$2:$AC$6232,'02_核算项'!$B$2:$B$6232,$A2,'02_核算项'!$M$2:$M$6232,"NH3") -> 0 | P2: =SUMIFS('02_核算项'!$AD$2:$AD$6232,'02_核算项'!$B$2:$B$6232,$A2,'02_核算项'!$M$2:$M$6232,"SO2") -> 9519.419 | Q2: =SUMIFS('02_核算项'!$AD$2:$AD$6232,'02_核算项'!$B$2:$B$6232,$A2,'02_核算项'!$M$2:$M$6232,"NOX") -> 4498.7654 | R2: =SUMIFS('02_核算项'!$AD$2:$AD$6232,'02_核算项'!$B$2:$B$6232,$A2,'02_核算项'!$M$2:$M$6232,"CO") -> 1599.9024 | S2: =SUMIFS('02_核算项'!$AD$2:$AD$6232,'02_核算项'!$B$2:$B$6232,$A2,'02_核算项'!$M$2:$M$6232,"VOCS") -> 31.998047 | T2: =SUMIFS('02_核算项'!$AD$2:$AD$6232,'02_核算项'!$B$2:$B$6232,$A2,'02_核算项'!$M$2:$M$6232,"PM10") -> 19456.813 | U2: =SUMIFS('02_核算项'!$AD$2:$AD$6232,'02_核算项'!$B$2:$B$6232,$A2,'02_核算项'!$M$2:$M$6232,"PM25") -> 5075.6902 | V2: =SUMIFS('02_核算项'!$AD$2:$AD$6232,'02_核算项'!$B$2:$B$6232,$A2,'02_核算项'!$M$2:$M$6232,"BC") -> 10.15138 | W2: =SUMIFS('02_核算项'!$AD$2:$AD$6232,'02_核算项'!$B$2:$B$6232,$A2,'02_核算项'!$M$2:$M$6232,"OC") -> 0 | X2: =SUMIFS('02_核算项'!$AD$2:$AD$6232,'02_核算项'!$B$2:$B$6232,$A2,'02_核算项'!$M$2:$M$6232,"NH3") -> 0 | Y2: 41
A3: SRC-RAW-008874CA96532DE69412 | B3: ENT-B420E4D245A5 | C3: 湛江市 | D3: 4430 | E3: 燃生物质锅炉 | F3: DA001 | G3: =SUMIFS('02_核算项'!$AC$2:$AC$6232,'02_核算项'!$B$2:$B$6232,$A3,'02_核算项'!$M$2:$M$6232,"SO2") -> 0 | H3: =SUMIFS('02_核算项'!$AC$2:$AC$6232,'02_核算项'!$B$2:$B$6232,$A3,'02_核算项'!$M$2:$M$6232,"NOX") -> 0 | I3: =SUMIFS('02_核算项'!$AC$2:$AC$6232,'02_核算项'!$B$2:$B$6232,$A3,'02_核算项'!$M$2:$M$6232,"CO") -> 0 | J3: =SUMIFS('02_核算项'!$AC$2:$AC$6232,'02_核算项'!$B$2:$B$6232,$A3,'02_核算项'!$M$2:$M$6232,"VOCS") -> 0 | K3: =SUMIFS('02_核算项'!$AC$2:$AC$6232,'02_核算项'!$B$2:$B$6232,$A3,'02_核算项'!$M$2:$M$6232,"PM10") -> 0 | L3: =SUMIFS('02_核算项'!$AC$2:$AC$6232,'02_核算项'!$B$2:$B$6232,$A3,'02_核算项'!$M$2:$M$6232,"PM25") -> 0 | M3: =SUMIFS('02_核算项'!$AC$2:$AC$6232,'02_核算项'!$B$2:$B$6232,$A3,'02_核算项'!$M$2:$M$6232,"BC") -> 0 | N3: =SUMIFS('02_核算项'!$AC$2:$AC$6232,'02_核算项'!$B$2:$B$6232,$A3,'02_核算项'!$M$2:$M$6232,"OC") -> 0 | O3: =SUMIFS('02_核算项'!$AC$2:$AC$6232,'02_核算项'!$B$2:$B$6232,$A3,'02_核算项'!$M$2:$M$6232,"NH3") -> 0 | P3: =SUMIFS('02_核算项'!$AD$2:$AD$6232,'02_核算项'!$B$2:$B$6232,$A3,'02_核算项'!$M$2:$M$6232,"SO2") -> 0 | Q3: =SUMIFS('02_核算项'!$AD$2:$AD$6232,'02_核算项'!$B$2:$B$6232,$A3,'02_核算项'!$M$2:$M$6232,"NOX") -> 0 | R3: =SUMIFS('02_核算项'!$AD$2:$AD$6232,'02_核算项'!$B$2:$B$6232,$A3,'02_核算项'!$M$2:$M$6232,"CO") -> 0 | S3: =SUMIFS('02_核算项'!$AD$2:$AD$6232,'02_核算项'!$B$2:$B$6232,$A3,'02_核算项'!$M$2:$M$6232,"VOCS") -> 0 | T3: =SUMIFS('02_核算项'!$AD$2:$AD$6232,'02_核算项'!$B$2:$B$6232,$A3,'02_核算项'!$M$2:$M$6232,"PM10") -> 0 | U3: =SUMIFS('02_核算项'!$AD$2:$AD$6232,'02_核算项'!$B$2:$B$6232,$A3,'02_核算项'!$M$2:$M$6232,"PM25") -> 0 | V3: =SUMIFS('02_核算项'!$AD$2:$AD$6232,'02_核算项'!$B$2:$B$6232,$A3,'02_核算项'!$M$2:$M$6232,"BC") -> 0 | W3: =SUMIFS('02_核算项'!$AD$2:$AD$6232,'02_核算项'!$B$2:$B$6232,$A3,'02_核算项'!$M$2:$M$6232,"OC") -> 0 | X3: =SUMIFS('02_核算项'!$AD$2:$AD$6232,'02_核算项'!$B$2:$B$6232,$A3,'02_核算项'!$M$2:$M$6232,"NH3") -> 0 | Y3: 49
A4: SRC-RAW-00C256E474D31C7B6CE7 | B4: ENT-092298654969 | C4: 湛江市 | D4: 4411 | E4: 燃煤锅炉 | F4: DA002 | G4: =SUMIFS('02_核算项'!$AC$2:$AC$6232,'02_核算项'!$B$2:$B$6232,$A4,'02_核算项'!$M$2:$M$6232,"SO2") -> 9631.5581 | H4: =SUMIFS('02_核算项'!$AC$2:$AC$6232,'02_核算项'!$B$2:$B$6232,$A4,'02_核算项'!$M$2:$M$6232,"NOX") -> 4255.1185 | I4: =SUMIFS('02_核算项'!$AC$2:$AC$6232,'02_核算项'!$B$2:$B$6232,$A4,'02_核算项'!$M$2:$M$6232,"CO") -> 1180.338 | J4: =SUMIFS('02_核算项'!$AC$2:$AC$6232,'02_核算项'!$B$2:$B$6232,$A4,'02_核算项'!$M$2:$M$6232,"VOCS") -> 23.60676 | K4: =SUMIFS('02_核算项'!$AC$2:$AC$6232,'02_核算项'!$B$2:$B$6232,$A4,'02_核算项'!$M$2:$M$6232,"PM10") -> 17805.546 | L4: =SUMIFS('02_核算项'!$AC$2:$AC$6232,'02_核算项'!$B$2:$B$6232,$A4,'02_核算项'!$M$2:$M$6232,"PM25") -> 4644.9251 | M4: =SUMIFS('02_核算项'!$AC$2:$AC$6232,'02_核算项'!$B$2:$B$6232,$A4,'02_核算项'!$M$2:$M$6232,"BC") -> 9.2898502 | N4: =SUMIFS('02_核算项'!$AC$2:$AC$6232,'02_核算项'!$B$2:$B$6232,$A4,'02_核算项'!$M$2:$M$6232,"OC") -> 0 | O4: =SUMIFS('02_核算项'!$AC$2:$AC$6232,'02_核算项'!$B$2:$B$6232,$A4,'02_核算项'!$M$2:$M$6232,"NH3") -> 94.42704 | P4: =SUMIFS('02_核算项'!$AD$2:$AD$6232,'02_核算项'!$B$2:$B$6232,$A4,'02_核算项'!$M$2:$M$6232,"SO2") -> 5778.9348 | Q4: =SUMIFS('02_核算项'!$AD$2:$AD$6232,'02_核算项'!$B$2:$B$6232,$A4,'02_核算项'!$M$2:$M$6232,"NOX") -> 1531.8427 | R4: =SUMIFS('02_核算项'!$AD$2:$AD$6232,'02_核算项'!$B$2:$B$6232,$A4,'02_核算项'!$M$2:$M$6232,"CO") -> 1180.338 | S4: =SUMIFS('02_核算项'!$AD$2:$AD$6232,'02_核算项'!$B$2:$B$6232,$A4,'02_核算项'!$M$2:$M$6232,"VOCS") -> 23.60676 | T4: =SUMIFS('02_核算项'!$AD$2:$AD$6232,'02_核算项'!$B$2:$B$6232,$A4,'02_核算项'!$M$2:$M$6232,"PM10") -> 317.40322 | U4: =SUMIFS('02_核算项'!$AD$2:$AD$6232,'02_核算项'!$B$2:$B$6232,$A4,'02_核算项'!$M$2:$M$6232,"PM25") -> 185.797 | V4: =SUMIFS('02_核算项'!$AD$2:$AD$6232,'02_核算项'!$B$2:$B$6232,$A4,'02_核算项'!$M$2:$M$6232,"BC") -> 0.37159401 | W4: =SUMIFS('02_核算项'!$AD$2:$AD$6232,'02_核算项'!$B$2:$B$6232,$A4,'02_核算项'!$M$2:$M$6232,"OC") -> 0 | X4: =SUMIFS('02_核算项'!$AD$2:$AD$6232,'02_核算项'!$B$2:$B$6232,$A4,'02_核算项'!$M$2:$M$6232,"NH3") -> 94.42704 | Y4: 24
A5: SRC-RAW-0109432DE0E295CD5108 | B5: ENT-8875BA3A892B | C5: 茂名市 | D5: 4411 | E5: 燃煤锅炉 | F5: DA001 | G5: =SUMIFS('02_核算项'!$AC$2:$AC$6232,'02_核算项'!$B$2:$B$6232,$A5,'02_核算项'!$M$2:$M$6232,"SO2") -> 1378.4019 | H5: =SUMIFS('02_核算项'!$AC$2:$AC$6232,'02_核算项'!$B$2:$B$6232,$A5,'02_核算项'!$M$2:$M$6232,"NOX") -> 1796.3188 | I5: =SUMIFS('02_核算项'!$AC$2:$AC$6232,'02_核算项'!$B$2:$B$6232,$A5,'02_核算项'!$M$2:$M$6232,"CO") -> 261.46745 | J5: =SUMIFS('02_核算项'!$AC$2:$AC$6232,'02_核算项'!$B$2:$B$6232,$A5,'02_核算项'!$M$2:$M$6232,"VOCS") -> 2801.7124 | K5: =SUMIFS('02_核算项'!$AC$2:$AC$6232,'02_核算项'!$B$2:$B$6232,$A5,'02_核算项'!$M$2:$M$6232,"PM10") -> 4010.4239 | L5: =SUMIFS('02_核算项'!$AC$2:$AC$6232,'02_核算项'!$B$2:$B$6232,$A5,'02_核算项'!$M$2:$M$6232,"PM25") -> 1003.1994 | M5: =SUMIFS('02_核算项'!$AC$2:$AC$6232,'02_核算项'!$B$2:$B$6232,$A5,'02_核算项'!$M$2:$M$6232,"BC") -> 5.2921902 | N5: =SUMIFS('02_核算项'!$AC$2:$AC$6232,'02_核算项'!$B$2:$B$6232,$A5,'02_核算项'!$M$2:$M$6232,"OC") -> 0.84772738 | O5: =SUMIFS('02_核算项'!$AC$2:$AC$6232,'02_核算项'!$B$2:$B$6232,$A5,'02_核算项'!$M$2:$M$6232,"NH3") -> 0 | P5: =SUMIFS('02_核算项'!$AD$2:$AD$6232,'02_核算项'!$B$2:$B$6232,$A5,'02_核算项'!$M$2:$M$6232,"SO2") -> 827.04115 | Q5: =SUMIFS('02_核算项'!$AD$2:$AD$6232,'02_核算项'!$B$2:$B$6232,$A5,'02_核算项'!$M$2:$M$6232,"NOX") -> 1796.3188 | R5: =SUMIFS('02_核算项'!$AD$2:$AD$6232,'02_核算项'!$B$2:$B$6232,$A5,'02_核算项'!$M$2:$M$6232,"CO") -> 261.46745 | S5: =SUMIFS('02_核算项'!$AD$2:$AD$6232,'02_核算项'!$B$2:$B$6232,$A5,'02_核算项'!$M$2:$M$6232,"VOCS") -> 2801.7124 | T5: =SUMIFS('02_核算项'!$AD$2:$AD$6232,'02_核算项'!$B$2:$B$6232,$A5,'02_核算项'!$M$2:$M$6232,"PM10") -> 130.36845 | U5: =SUMIFS('02_核算项'!$AD$2:$AD$6232,'02_核算项'!$B$2:$B$6232,$A5,'02_核算项'!$M$2:$M$6232,"PM25") -> 70.223959 | V5: =SUMIFS('02_核算项'!$AD$2:$AD$6232,'02_核算项'!$B$2:$B$6232,$A5,'02_核算项'!$M$2:$M$6232,"BC") -> 0.37045331 | W5: =SUMIFS('02_核算项'!$AD$2:$AD$6232,'02_核算项'!$B$2:$B$6232,$A5,'02_核算项'!$M$2:$M$6232,"OC") -> 0.059340917 | X5: =SUMIFS('02_核算项'!$AD$2:$AD$6232,'02_核算项'!$B$2:$B$6232,$A5,'02_核算项'!$M$2:$M$6232,"NH3") -> 0 | Y5: 50
A6: SRC-RAW-017C98E5B9CB826F2F33 | B6: ENT-8B49EFE262D1 | C6: 珠海市 | D6: 4412 | E6: 燃气轮机 | F6: DA001 | G6: =SUMIFS('02_核算项'!$AC$2:$AC$6232,'02_核算项'!$B$2:$B$6232,$A6,'02_核算项'!$M$2:$M$6232,"SO2") -> 0 | H6: =SUMIFS('02_核算项'!$AC$2:$AC$6232,'02_核算项'!$B$2:$B$6232,$A6,'02_核算项'!$M$2:$M$6232,"NOX") -> 454.18656 | I6: =SUMIFS('02_核算项'!$AC$2:$AC$6232,'02_核算项'!$B$2:$B$6232,$A6,'02_核算项'!$M$2:$M$6232,"CO") -> 144.01037 | J6: =SUMIFS('02_核算项'!$AC$2:$AC$6232,'02_核算项'!$B$2:$B$6232,$A6,'02_核算项'!$M$2:$M$6232,"VOCS") -> 2.2155442 | K6: =SUMIFS('02_核算项'!$AC$2:$AC$6232,'02_核算项'!$B$2:$B$6232,$A6,'02_核算项'!$M$2:$M$6232,"PM10") -> 3.3233163 | L6: =SUMIFS('02_核算项'!$AC$2:$AC$6232,'02_核算项'!$B$2:$B$6232,$A6,'02_核算项'!$M$2:$M$6232,"PM25") -> 3.3233163 | M6: =SUMIFS('02_核算项'!$AC$2:$AC$6232,'02_核算项'!$B$2:$B$6232,$A6,'02_核算项'!$M$2:$M$6232,"BC") -> 0 | N6: =SUMIFS('02_核算项'!$AC$2:$AC$6232,'02_核算项'!$B$2:$B$6232,$A6,'02_核算项'!$M$2:$M$6232,"OC") -> 0 | O6: =SUMIFS('02_核算项'!$AC$2:$AC$6232,'02_核算项'!$B$2:$B$6232,$A6,'02_核算项'!$M$2:$M$6232,"NH3") -> 0 | P6: =SUMIFS('02_核算项'!$AD$2:$AD$6232,'02_核算项'!$B$2:$B$6232,$A6,'02_核算项'!$M$2:$M$6232,"SO2") -> 0 | Q6: =SUMIFS('02_核算项'!$AD$2:$AD$6232,'02_核算项'!$B$2:$B$6232,$A6,'02_核算项'!$M$2:$M$6232,"NOX") -> 354.26552 | R6: =SUMIFS('02_核算项'!$AD$2:$AD$6232,'02_核算项'!$B$2:$B$6232,$A6,'02_核算项'!$M$2:$M$6232,"CO") -> 144.01037 | S6: =SUMIFS('02_核算项'!$AD$2:$AD$6232,'02_核算项'!$B$2:$B$6232,$A6,'02_核算项'!$M$2:$M$6232,"VOCS") -> 2.2155442 | T6: =SUMIFS('02_核算项'!$AD$2:$AD$6232,'02_核算项'!$B$2:$B$6232,$A6,'02_核算项'!$M$2:$M$6232,"PM10") -> 3.3233163 | U6: =SUMIFS('02_核算项'!$AD$2:$AD$6232,'02_核算项'!$B$2:$B$6232,$A6,'02_核算项'!$M$2:$M$6232,"PM25") -> 3.3233163 | V6: =SUMIFS('02_核算项'!$AD$2:$AD$6232,'02_核算项'!$B$2:$B$6232,$A6,'02_核算项'!$M$2:$M$6232,"BC") -> 0 | W6: =SUMIFS('02_核算项'!$AD$2:$AD$6232,'02_核算项'!$B$2:$B$6232,$A6,'02_核算项'!$M$2:$M$6232,"OC") -> 0 | X6: =SUMIFS('02_核算项'!$AD$2:$AD$6232,'02_核算项'!$B$2:$B$6232,$A6,'02_核算项'!$M$2:$M$6232,"NH3") -> 0 | Y6: 32
A7: SRC-RAW-0180EDF55F46EA2F4653 | B7: ENT-5B3225588C52 | C7: 中山市 | D7: 4412 | E7: 燃气轮机 | F7: DA002 | G7: =SUMIFS('02_核算项'!$AC$2:$AC$6232,'02_核算项'!$B$2:$B$6232,$A7,'02_核算项'!$M$2:$M$6232,"SO2") -> 0 | H7: =SUMIFS('02_核算项'!$AC$2:$AC$6232,'02_核算项'!$B$2:$B$6232,$A7,'02_核算项'!$M$2:$M$6232,"NOX") -> 1280.1223 | I7: =SUMIFS('02_核算项'!$AC$2:$AC$6232,'02_核算项'!$B$2:$B$6232,$A7,'02_核算项'!$M$2:$M$6232,"CO") -> 405.89245 | J7: =SUMIFS('02_核算项'!$AC$2:$AC$6232,'02_核算项'!$B$2:$B$6232,$A7,'02_核算项'!$M$2:$M$6232,"VOCS") -> 6.2444992 | K7: =SUMIFS('02_核算项'!$AC$2:$AC$6232,'02_核算项'!$B$2:$B$6232,$A7,'02_核算项'!$M$2:$M$6232,"PM10") -> 9.3667488 | L7: =SUMIFS('02_核算项'!$AC$2:$AC$6232,'02_核算项'!$B$2:$B$6232,$A7,'02_核算项'!$M$2:$M$6232,"PM25") -> 9.3667488 | M7: =SUMIFS('02_核算项'!$AC$2:$AC$6232,'02_核算项'!$B$2:$B$6232,$A7,'02_核算项'!$M$2:$M$6232,"BC") -> 0 | N7: =SUMIFS('02_核算项'!$AC$2:$AC$6232,'02_核算项'!$B$2:$B$6232,$A7,'02_核算项'!$M$2:$M$6232,"OC") -> 0 | O7: =SUMIFS('02_核算项'!$AC$2:$AC$6232,'02_核算项'!$B$2:$B$6232,$A7,'02_核算项'!$M$2:$M$6232,"NH3") -> 0 | P7: =SUMIFS('02_核算项'!$AD$2:$AD$6232,'02_核算项'!$B$2:$B$6232,$A7,'02_核算项'!$M$2:$M$6232,"SO2") -> 0 | Q7: =SUMIFS('02_核算项'!$AD$2:$AD$6232,'02_核算项'!$B$2:$B$6232,$A7,'02_核算项'!$M$2:$M$6232,"NOX") -> 460.84404 | R7: =SUMIFS('02_核算项'!$AD$2:$AD$6232,'02_核算项'!$B$2:$B$6232,$A7,'02_核算项'!$M$2:$M$6232,"CO") -> 405.89245 | S7: =SUMIFS('02_核算项'!$AD$2:$AD$6232,'02_核算项'!$B$2:$B$6232,$A7,'02_核算项'!$M$2:$M$6232,"VOCS") -> 6.2444992 | T7: =SUMIFS('02_核算项'!$AD$2:$AD$6232,'02_核算项'!$B$2:$B$6232,$A7,'02_核算项'!$M$2:$M$6232,"PM10") -> 4.027702 | U7: =SUMIFS('02_核算项'!$AD$2:$AD$6232,'02_核算项'!$B$2:$B$6232,$A7,'02_核算项'!$M$2:$M$6232,"PM25") -> 4.027702 | V7: =SUMIFS('02_核算项'!$AD$2:$AD$6232,'02_核算项'!$B$2:$B$6232,$A7,'02_核算项'!$M$2:$M$6232,"BC") -> 0 | W7: =SUMIFS('02_核算项'!$AD$2:$AD$6232,'02_核算项'!$B$2:$B$6232,$A7,'02_核算项'!$M$2:$M$6232,"OC") -> 0 | Y7: 29
A8: SRC-RAW-0249A5BFBA1950F087DA | B8: ENT-5B63BBAC773E | C8: 广州市 | D8: 4417 | E8: 燃生物质锅炉 | F8: DA007 | G8: =SUMIFS('02_核算项'!$AC$2:$AC$6232,'02_核算项'!$B$2:$B$6232,$A8,'02_核算项'!$M$2:$M$6232,"SO2") -> 0 | H8: =SUMIFS('02_核算项'!$AC$2:$AC$6232,'02_核算项'!$B$2:$B$6232,$A8,'02_核算项'!$M$2:$M$6232,"NOX") -> 0 | I8: =SUMIFS('02_核算项'!$AC$2:$AC$6232,'02_核算项'!$B$2:$B$6232,$A8,'02_核算项'!$M$2:$M$6232,"CO") -> 0 | J8: =SUMIFS('02_核算项'!$AC$2:$AC$6232,'02_核算项'!$B$2:$B$6232,$A8,'02_核算项'!$M$2:$M$6232,"VOCS") -> 0 | K8: =SUMIFS('02_核算项'!$AC$2:$AC$6232,'02_核算项'!$B$2:$B$6232,$A8,'02_核算项'!$M$2:$M$6232,"PM10") -> 0 | L8: =SUMIFS('02_核算项'!$AC$2:$AC$6232,'02_核算项'!$B$2:$B$6232,$A8,'02_核算项'!$M$2:$M$6232,"PM25") -> 0 | M8: =SUMIFS('02_核算项'!$AC$2:$AC$6232,'02_核算项'!$B$2:$B$6232,$A8,'02_核算项'!$M$2:$M$6232,"BC") -> 0 | N8: =SUMIFS('02_核算项'!$AC$2:$AC$6232,'02_核算项'!$B$2:$B$6232,$A8,'02_核算项'!$M$2:$M$6232,"OC") -> 0 | O8: =SUMIFS('02_核算项'!$AC$2:$AC$6232,'02_核算项'!$B$2:$B$6232,$A8,'02_核算项'!$M$2:$M$6232,"NH3") -> 0 | X8: =SUMIFS('02_核算项'!$AD$2:$AD$6232,'02_核算项'!$B$2:$B$6232,$A8,'02_核算项'!$M$2:$M$6232,"NH3") -> 0 | Y8: 48
A9: SRC-RAW-02F1AE3DC01E0E3EA7CE | B9: ENT-2D5DCA2B3D88 | C9: 汕头市 | D9: 4417 | E9: 燃生物质锅炉 | F9: DA003 | G9: =SUMIFS('02_核算项'!$AC$2:$AC$6232,'02_核算项'!$B$2:$B$6232,$A9,'02_核算项'!$M$2:$M$6232,"SO2") -> 0 | H9: =SUMIFS('02_核算项'!$AC$2:$AC$6232,'02_核算项'!$B$2:$B$6232,$A9,'02_核算项'!$M$2:$M$6232,"NOX") -> 0 | I9: =SUMIFS('02_核算项'!$AC$2:$AC$6232,'02_核算项'!$B$2:$B$6232,$A9,'02_核算项'!$M$2:$M$6232,"CO") -> 0 | J9: =SUMIFS('02_核算项'!$AC$2:$AC$6232,'02_核算项'!$B$2:$B$6232,$A9,'02_核算项'!$M$2:$M$6232,"VOCS") -> 0 | K9: =SUMIFS('02_核算项'!$AC$2:$AC$6232,'02_核算项'!$B$2:$B$6232,$A9,'02_核算项'!$M$2:$M$6232,"PM10") -> 0 | L9: =SUMIFS('02_核算项'!$AC$2:$AC$6232,'02_核算项'!$B$2:$B$6232,$A9,'02_核算项'!$M$2:$M$6232,"PM25") -> 0 | M9: =SUMIFS('02_核算项'!$AC$2:$AC$6232,'02_核算项'!$B$2:$B$6232,$A9,'02_核算项'!$M$2:$M$6232,"BC") -> 0 | N9: =SUMIFS('02_核算项'!$AC$2:$AC$6232,'02_核算项'!$B$2:$B$6232,$A9,'02_核算项'!$M$2:$M$6232,"OC") -> 0 | O9: =SUMIFS('02_核算项'!$AC$2:$AC$6232,'02_核算项'!$B$2:$B$6232,$A9,'02_核算项'!$M$2:$M$6232,"NH3") -> 0 | Y9: 41
A10: SRC-RAW-031B3589BCDCF633B0EA | B10: ENT-99B21D210819 | C10: 韶关市 | D10: 4411 | E10: 燃煤锅炉 | F10: DA002 | G10: =SUMIFS('02_核算项'!$AC$2:$AC$6232,'02_核算项'!$B$2:$B$6232,$A10,'02_核算项'!$M$2:$M$6232,"SO2") -> 9716.8797 | H10: =SUMIFS('02_核算项'!$AC$2:$AC$6232,'02_核算项'!$B$2:$B$6232,$A10,'02_核算项'!$M$2:$M$6232,"NOX") -> 4965.1809 | I10: =SUMIFS('02_核算项'!$AC$2:$AC$6232,'02_核算项'!$B$2:$B$6232,$A10,'02_核算项'!$M$2:$M$6232,"CO") -> 1377.304 | J10: =SUMIFS('02_核算项'!$AC$2:$AC$6232,'02_核算项'!$B$2:$B$6232,$A10,'02_核算项'!$M$2:$M$6232,"VOCS") -> 27.54608 | K10: =SUMIFS('02_核算项'!$AC$2:$AC$6232,'02_核算项'!$B$2:$B$6232,$A10,'02_核算项'!$M$2:$M$6232,"PM10") -> 23330.841 | L10: =SUMIFS('02_核算项'!$AC$2:$AC$6232,'02_核算项'!$B$2:$B$6232,$A10,'02_核算项'!$M$2:$M$6232,"PM25") -> 6086.3064 | M10: =SUMIFS('02_核算项'!$AC$2:$AC$6232,'02_核算项'!$B$2:$B$6232,$A10,'02_核算项'!$M$2:$M$6232,"BC") -> 12.172613 | N10: =SUMIFS('02_核算项'!$AC$2:$AC$6232,'02_核算项'!$B$2:$B$6232,$A10,'02_核算项'!$M$2:$M$6232,"OC") -> 0 | O10: =SUMIFS('02_核算项'!$AC$2:$AC$6232,'02_核算项'!$B$2:$B$6232,$A10,'02_核算项'!$M$2:$M$6232,"NH3") -> 110.18432 | P10: =SUMIFS('02_核算项'!$AD$2:$AD$6232,'02_核算项'!$B$2:$B$6232,$A10,'02_核算项'!$M$2:$M$6232,"SO2") -> 1943.3759 | Q10: =SUMIFS('02_核算项'!$AD$2:$AD$6232,'02_核算项'!$B$2:$B$6232,$A10,'02_核算项'!$M$2:$M$6232,"NOX") -> 1787.4651 | R10: =SUMIFS('02_核算项'!$AD$2:$AD$6232,'02_核算项'!$B$2:$B$6232,$A10,'02_核算项'!$M$2:$M$6232,"CO") -> 1377.304 | S10: =SUMIFS('02_核算项'!$AD$2:$AD$6232,'02_核算项'!$B$2:$B$6232,$A10,'02_核算项'!$M$2:$M$6232,"VOCS") -> 27.54608 | T10: =SUMIFS('02_核算项'!$AD$2:$AD$6232,'02_核算项'!$B$2:$B$6232,$A10,'02_核算项'!$M$2:$M$6232,"PM10") -> 415.8976 | U10: =SUMIFS('02_核算项'!$AD$2:$AD$6232,'02_核算项'!$B$2:$B$6232,$A10,'02_核算项'!$M$2:$M$6232,"PM25") -> 243.45226 | V10: =SUMIFS('02_核算项'!$AD$2:$AD$6232,'02_核算项'!$B$2:$B$6232,$A10,'02_核算项'!$M$2:$M$6232,"BC") -> 0.48690451 | W10: =SUMIFS('02_核算项'!$AD$2:$AD$6232,'02_核算项'!$B$2:$B$6232,$A10,'02_核算项'!$M$2:$M$6232,"OC") -> 0 | X10: =SUMIFS('02_核算项'!$AD$2:$AD$6232,'02_核算项'!$B$2:$B$6232,$A10,'02_核算项'!$M$2:$M$6232,"NH3") -> 110.18432 | Y10: 15
A11: SRC-RAW-034EA11B7545A4E80FF5 | B11: ENT-16086C6FA96F | C11: 珠海市 | D11: 4411 | E11: 燃煤锅炉 | F11: DA002 | G11: =SUMIFS('02_核算项'!$AC$2:$AC$6232,'02_核算项'!$B$2:$B$6232,$A11,'02_核算项'!$M$2:$M$6232,"SO2") -> 15477.419 | H11: =SUMIFS('02_核算项'!$AC$2:$AC$6232,'02_核算项'!$B$2:$B$6232,$A11,'02_核算项'!$M$2:$M$6232,"NOX") -> 10761.091 | I11: =SUMIFS('02_核算项'!$AC$2:$AC$6232,'02_核算项'!$B$2:$B$6232,$A11,'02_核算项'!$M$2:$M$6232,"CO") -> 2985.0375 | J11: =SUMIFS('02_核算项'!$AC$2:$AC$6232,'02_核算项'!$B$2:$B$6232,$A11,'02_核算项'!$M$2:$M$6232,"VOCS") -> 59.701449 | K11: =SUMIFS('02_核算项'!$AC$2:$AC$6232,'02_核算项'!$B$2:$B$6232,$A11,'02_核算项'!$M$2:$M$6232,"PM10") -> 38567.388 | L11: =SUMIFS('02_核算项'!$AC$2:$AC$6232,'02_核算项'!$B$2:$B$6232,$A11,'02_核算项'!$M$2:$M$6232,"PM25") -> 10061.06 | M11: =SUMIFS('02_核算项'!$AC$2:$AC$6232,'02_核算项'!$B$2:$B$6232,$A11,'02_核算项'!$M$2:$M$6232,"BC") -> 20.122173 | N11: =SUMIFS('02_核算项'!$AC$2:$AC$6232,'02_核算项'!$B$2:$B$6232,$A11,'02_核算项'!$M$2:$M$6232,"OC") -> 0.00023652 | O11: =SUMIFS('02_核算项'!$AC$2:$AC$6232,'02_核算项'!$B$2:$B$6232,$A11,'02_核算项'!$M$2:$M$6232,"NH3") -> 238.80272 | P11: =SUMIFS('02_核算项'!$AD$2:$AD$6232,'02_核算项'!$B$2:$B$6232,$A11,'02_核算项'!$M$2:$M$6232,"SO2") -> 3095.4838 | Q11: =SUMIFS('02_核算项'!$AD$2:$AD$6232,'02_核算项'!$B$2:$B$6232,$A11,'02_核算项'!$M$2:$M$6232,"NOX") -> 3873.9929 | R11: =SUMIFS('02_核算项'!$AD$2:$AD$6232,'02_核算项'!$B$2:$B$6232,$A11,'02_核算项'!$M$2:$M$6232,"CO") -> 2985.0375 | S11: =SUMIFS('02_核算项'!$AD$2:$AD$6232,'02_核算项'!$B$2:$B$6232,$A11,'02_核算项'!$M$2:$M$6232,"VOCS") -> 59.701449 | T11: =SUMIFS('02_核算项'!$AD$2:$AD$6232,'02_核算项'!$B$2:$B$6232,$A11,'02_核算项'!$M$2:$M$6232,"PM10") -> 687.50569 | U11: =SUMIFS('02_核算项'!$AD$2:$AD$6232,'02_核算项'!$B$2:$B$6232,$A11,'02_核算项'!$M$2:$M$6232,"PM25") -> 402.4424 | V11: =SUMIFS('02_核算项'!$AD$2:$AD$6232,'02_核算项'!$B$2:$B$6232,$A11,'02_核算项'!$M$2:$M$6232,"BC") -> 0.80488693 | W11: =SUMIFS('02_核算项'!$AD$2:$AD$6232,'02_核算项'!$B$2:$B$6232,$A11,'02_核算项'!$M$2:$M$6232,"OC") -> 9.4608e-06 | X11: =SUMIFS('02_核算项'!$AD$2:$AD$6232,'02_核算项'!$B$2:$B$6232,$A11,'02_核算项'!$M$2:$M$6232,"NH3") -> 238.80272 | Y11: 29
A12: SRC-RAW-03DE8EF23ED7B791BADC | B12: ENT-0ACC73BB16FC | C12: 韶关市 | D12: 4411 | E12: 燃煤锅炉 | F12: DA002 | G12: =SUMIFS('02_核算项'!$AC$2:$AC$6232,'02_核算项'!$B$2:$B$6232,$A12,'02_核算项'!$M$2:$M$6232,"SO2") -> 30925.506 | H12: =SUMIFS('02_核算项'!$AC$2:$AC$6232,'02_核算项'!$B$2:$B$6232,$A12,'02_核算项'!$M$2:$M$6232,"NOX") -> 12777.789 | I12: =SUMIFS('02_核算项'!$AC$2:$AC$6232,'02_核算项'!$B$2:$B$6232,$A12,'02_核算项'!$M$2:$M$6232,"CO") -> 3544.463 | J12: =SUMIFS('02_核算项'!$AC$2:$AC$6232,'02_核算项'!$B$2:$B$6232,$A12,'02_核算项'!$M$2:$M$6232,"VOCS") -> 70.88926 | K12: =SUMIFS('02_核算项'!$AC$2:$AC$6232,'02_核算项'!$B$2:$B$6232,$A12,'02_核算项'!$M$2:$M$6232,"PM10") -> 136188.97 | L12: =SUMIFS('02_核算项'!$AC$2:$AC$6232,'02_核算项'!$B$2:$B$6232,$A12,'02_核算项'!$M$2:$M$6232,"PM25") -> 32873.199 | M12: =SUMIFS('02_核算项'!$AC$2:$AC$6232,'02_核算项'!$B$2:$B$6232,$A12,'02_核算项'!$M$2:$M$6232,"BC") -> 65.746398 | N12: =SUMIFS('02_核算项'!$AC$2:$AC$6232,'02_核算项'!$B$2:$B$6232,$A12,'02_核算项'!$M$2:$M$6232,"OC") -> 0 | O12: =SUMIFS('02_核算项'!$AC$2:$AC$6232,'02_核算项'!$B$2:$B$6232,$A12,'02_核算项'!$M$2:$M$6232,"NH3") -> 0 | P12: =SUMIFS('02_核算项'!$AD$2:$AD$6232,'02_核算项'!$B$2:$B$6232,$A12,'02_核算项'!$M$2:$M$6232,"SO2") -> 30925.506 | Q12: =SUMIFS('02_核算项'!$AD$2:$AD$6232,'02_核算项'!$B$2:$B$6232,$A12,'02_核算项'!$M$2:$M$6232,"NOX") -> 9966.6755 | R12: =SUMIFS('02_核算项'!$AD$2:$AD$6232,'02_核算项'!$B$2:$B$6232,$A12,'02_核算项'!$M$2:$M$6232,"CO") -> 3544.463 | S12: =SUMIFS('02_核算项'!$AD$2:$AD$6232,'02_核算项'!$B$2:$B$6232,$A12,'02_核算项'!$M$2:$M$6232,"VOCS") -> 70.88926 | T12: =SUMIFS('02_核算项'!$AD$2:$AD$6232,'02_核算项'!$B$2:$B$6232,$A12,'02_核算项'!$M$2:$M$6232,"PM10") -> 136188.97 | U12: =SUMIFS('02_核算项'!$AD$2:$AD$6232,'02_核算项'!$B$2:$B$6232,$A12,'02_核算项'!$M$2:$M$6232,"PM25") -> 32873.199 | V12: =SUMIFS('02_核算项'!$AD$2:$AD$6232,'02_核算项'!$B$2:$B$6232,$A12,'02_核算项'!$M$2:$M$6232,"BC") -> 65.746398 | W12: =SUMIFS('02_核算项'!$AD$2:$AD$6232,'02_核算项'!$B$2:$B$6232,$A12,'02_核算项'!$M$2:$M$6232,"OC") -> 0 | X12: =SUMIFS('02_核算项'!$AD$2:$AD$6232,'02_核算项'!$B$2:$B$6232,$A12,'02_核算项'!$M$2:$M$6232,"NH3") -> 0 | Y12: 80
A13: SRC-RAW-052001AE00EAE9CB3DBA | B13: ENT-20040C4B08B0 | C13: 韶关市 | D13: 4417 | E13: 燃生物质锅炉 | F13: DA001 | G13: =SUMIFS('02_核算项'!$AC$2:$AC$6232,'02_核算项'!$B$2:$B$6232,$A13,'02_核算项'!$M$2:$M$6232,"SO2") -> 0 | H13: =SUMIFS('02_核算项'!$AC$2:$AC$6232,'02_核算项'!$B$2:$B$6232,$A13,'02_核算项'!$M$2:$M$6232,"NOX") -> 0 | I13: =SUMIFS('02_核算项'!$AC$2:$AC$6232,'02_核算项'!$B$2:$B$6232,$A13,'02_核算项'!$M$2:$M$6232,"CO") -> 0 | J13: =SUMIFS('02_核算项'!$AC$2:$AC$6232,'02_核算项'!$B$2:$B$6232,$A13,'02_核算项'!$M$2:$M$6232,"VOCS") -> 0 | K13: =SUMIFS('02_核算项'!$AC$2:$AC$6232,'02_核算项'!$B$2:$B$6232,$A13,'02_核算项'!$M$2:$M$6232,"PM10") -> 0 | L13: =SUMIFS('02_核算项'!$AC$2:$AC$6232,'02_核算项'!$B$2:$B$6232,$A13,'02_核算项'!$M$2:$M$6232,"PM25") -> 0 | M13: =SUMIFS('02_核算项'!$AC$2:$AC$6232,'02_核算项'!$B$2:$B$6232,$A13,'02_核算项'!$M$2:$M$6232,"BC") -> 0 | N13: =SUMIFS('02_核算项'!$AC$2:$AC$6232,'02_核算项'!$B$2:$B$6232,$A13,'02_核算项'!$M$2:$M$6232,"OC") -> 0 | O13: =SUMIFS('02_核算项'!$AC$2:$AC$6232,'02_核算项'!$B$2:$B$6232,$A13,'02_核算项'!$M$2:$M$6232,"NH3") -> 0 | P13: =SUMIFS('02_核算项'!$AD$2:$AD$6232,'02_核算项'!$B$2:$B$6232,$A13,'02_核算项'!$M$2:$M$6232,"SO2") -> 0 | Q13: =SUMIFS('02_核算项'!$AD$2:$AD$6232,'02_核算项'!$B$2:$B$6232,$A13,'02_核算项'!$M$2:$M$6232,"NOX") -> 0 | R13: =SUMIFS('02_核算项'!$AD$2:$AD$6232,'02_核算项'!$B$2:$B$6232,$A13,'02_核算项'!$M$2:$M$6232,"CO") -> 0 | S13: =SUMIFS('02_核算项'!$AD$2:$AD$6232,'02_核算项'!$B$2:$B$6232,$A13,'02_核算项'!$M$2:$M$6232,"VOCS") -> 0 | T13: =SUMIFS('02_核算项'!$AD$2:$AD$6232,'02_核算项'!$B$2:$B$6232,$A13,'02_核算项'!$M$2:$M$6232,"PM10") -> 0 | U13: =SUMIFS('02_核算项'!$AD$2:$AD$6232,'02_核算项'!$B$2:$B$6232,$A13,'02_核算项'!$M$2:$M$6232,"PM25") -> 0 | V13: =SUMIFS('02_核算项'!$AD$2:$AD$6232,'02_核算项'!$B$2:$B$6232,$A13,'02_核算项'!$M$2:$M$6232,"BC") -> 0 | W13: =SUMIFS('02_核算项'!$AD$2:$AD$6232,'02_核算项'!$B$2:$B$6232,$A13,'02_核算项'!$M$2:$M$6232,"OC") -> 0 | X13: =SUMIFS('02_核算项'!$AD$2:$AD$6232,'02_核算项'!$B$2:$B$6232,$A13,'02_核算项'!$M$2:$M$6232,"NH3") -> 0 | Y13: 58
A14: SRC-RAW-0543F60FDC1976D763BF | B14: ENT-092298654969 | C14: 湛江市 | D14: 4411 | E14: 燃煤锅炉 | F14: DA004 | G14: =SUMIFS('02_核算项'!$AC$2:$AC$6232,'02_核算项'!$B$2:$B$6232,$A14,'02_核算项'!$M$2:$M$6232,"SO2") -> 11773.917 | H14: =SUMIFS('02_核算项'!$AC$2:$AC$6232,'02_核算项'!$B$2:$B$6232,$A14,'02_核算项'!$M$2:$M$6232,"NOX") -> 5201.5896 | I14: =SUMIFS('02_核算项'!$AC$2:$AC$6232,'02_核算项'!$B$2:$B$6232,$A14,'02_核算项'!$M$2:$M$6232,"CO") -> 1442.882 | J14: =SUMIFS('02_核算项'!$AC$2:$AC$6232,'02_核算项'!$B$2:$B$6232,$A14,'02_核算项'!$M$2:$M$6232,"VOCS") -> 28.85764 | K14: =SUMIFS('02_核算项'!$AC$2:$AC$6232,'02_核算项'!$B$2:$B$6232,$A14,'02_核算项'!$M$2:$M$6232,"PM10") -> 21766.055 | L14: =SUMIFS('02_核算项'!$AC$2:$AC$6232,'02_核算项'!$B$2:$B$6232,$A14,'02_核算项'!$M$2:$M$6232,"PM25") -> 5678.1014 | M14: =SUMIFS('02_核算项'!$AC$2:$AC$6232,'02_核算项'!$B$2:$B$6232,$A14,'02_核算项'!$M$2:$M$6232,"BC") -> 11.356203 | N14: =SUMIFS('02_核算项'!$AC$2:$AC$6232,'02_核算项'!$B$2:$B$6232,$A14,'02_核算项'!$M$2:$M$6232,"OC") -> 0 | O14: =SUMIFS('02_核算项'!$AC$2:$AC$6232,'02_核算项'!$B$2:$B$6232,$A14,'02_核算项'!$M$2:$M$6232,"NH3") -> 115.43056 | P14: =SUMIFS('02_核算项'!$AD$2:$AD$6232,'02_核算项'!$B$2:$B$6232,$A14,'02_核算项'!$M$2:$M$6232,"SO2") -> 7064.3503 | Q14: =SUMIFS('02_核算项'!$AD$2:$AD$6232,'02_核算项'!$B$2:$B$6232,$A14,'02_核算项'!$M$2:$M$6232,"NOX") -> 1872.5723 | R14: =SUMIFS('02_核算项'!$AD$2:$AD$6232,'02_核算项'!$B$2:$B$6232,$A14,'02_核算项'!$M$2:$M$6232,"CO") -> 1442.882 | S14: =SUMIFS('02_核算项'!$AD$2:$AD$6232,'02_核算项'!$B$2:$B$6232,$A14,'02_核算项'!$M$2:$M$6232,"VOCS") -> 28.85764 | T14: =SUMIFS('02_核算项'!$AD$2:$AD$6232,'02_核算项'!$B$2:$B$6232,$A14,'02_核算项'!$M$2:$M$6232,"PM10") -> 388.0036 | U14: =SUMIFS('02_核算项'!$AD$2:$AD$6232,'02_核算项'!$B$2:$B$6232,$A14,'02_核算项'!$M$2:$M$6232,"PM25") -> 227.12406 | V14: =SUMIFS('02_核算项'!$AD$2:$AD$6232,'02_核算项'!$B$2:$B$6232,$A14,'02_核算项'!$M$2:$M$6232,"BC") -> 0.45424811 | W14: =SUMIFS('02_核算项'!$AD$2:$AD$6232,'02_核算项'!$B$2:$B$6232,$A14,'02_核算项'!$M$2:$M$6232,"OC") -> 0 | X14: =SUMIFS('02_核算项'!$AD$2:$AD$6232,'02_核算项'!$B$2:$B$6232,$A14,'02_核算项'!$M$2:$M$6232,"NH3") -> 115.43056 | Y14: 24
